Workbook
Name 문서명: #REF!
Name 문서명: 표지!$O$5
Name 프로젝트명: #REF!
Name 프로젝트명: 표지!$O$4

Sheet 표지
C5: [AI거버넌스]
C7: AI거버넌스 지원도구 설계-
C8: 별첨4. AI 위험등급평가서
C10: Version 1.0
C11: 46078

Sheet 제개정이력
A3: 작성/검토자
A4: 구분 | B4: 소속 | C4: 직급 | D4: 성명 | E4: 일자
A5: 작성자 | B5: EY컨설팅 | C5: 부장 | D5: 나종민 | E5: 46034
A6: 검토자
A7: 승인자
A9: 제/개정 이력 | C9: 제/개정 이력
A10: 버전 | B10: 제/개정 페이지 및 수정 내용 | D10: 제/개정 일자 | E10: 제/개정자
A11: 0.1 | B11: 초안 작성 | D11: 46034 | E11: 나종민
A12: 0.5 | B12: AI RMF 반영 | D12: 46050 | E12: 김승욱
A13: 0.51 | B13: 내용 검토 및 추가 요청사항 반영 | D13: 46051 | E13: 나종민
A14: 0.6 | B14: 위험 항목 추가 및 일부 서식 개정 | D14: 46052 | E14: 김승욱
A15: 0.61 | B15: 위험 평가 및 완화 방안 정리 | D15: 46056 | E15: 김승욱
A16: 0.62 | B16: 위험 평가 및 완화 방안 취합 및 정리 | D16: 46058 | E16: 김승욱
A17: 0.8 | B17: 초안 작성 완료 | D17: 46059 | E17: 김승욱
A18: 0.9 | B18: 적용 대상 세부 기준 추가 요청사항 반영 | D18: 46065 | E18: 나종민
A19: 0.91 | B19: 위험 식별 및 평가 방안 전면개편 및 평가세트 기반 평가 방식 적용 | D19: 46066 | E19: 김승욱
A20: 0.92 | B20: 고영향 AI의 위험도 조정(고위험/초고위험) | D20: 46073 | E20: 김승욱
A21: 0.93 | B21: 영향&안전성 여부 판단, 위험평가항목 척도 추가 | D21: 46077 | E21: 나종민
A22: 1.0 | B22: 버전 업데이트 | D22: 46078 | E22: 나종민

Sheet 개요
B3: ■ 위험등급 평가서 구성
C5: Sheet | D5: 작성 내용 | F5: 작성 담당
C6: 1. 영향 & 안전성 여부 판단서 | D6: [AI서비스기획] - 고영향 AI 여부 판단 [AI서비스기획/개발] - 고영향 AI 해당 시, 안전성 여부 판단 수행 (기획·설계 단계에서는 사전판단 / 개발 단계에서 안전성 적용 대상 최종 판단 수행) | F6: AI서비스기획 AI개발
C7: 2. 위험 식별 및 평가 | D7: [AI서비스기획/개발] - 평가를 수행하기 위한 평가 세트 선택 - 해당 서비스에 해당하는 위험 식별 및 사유 작성 - 식별한 AI 위험에 대한 상세 완화 방안 작성 - 완화 방안의 적용에 따라, 예상되는 잔여 위험에 대한 평가 수행 [AI거버넌스] - 위험 항목별 평가 결과 검토 - 검토 결과 수정 필요 시 의견 작성 및 재수행 요청 | F7: AI서비스기획 AI개발 AI거버넌스
C8: 3. AI 위험 평가 보고서 | D8: - AI 서비스 위험평가 결과 확인 - AI 서비스명, 담당부서/담당자 작성 | F8: AI서비스기획
C9: 평가 결과 요약 | D9: - 각 시트별 이상여부 확인 (작성내용 없음) | F9: -
C10: AI 위험평가 기준자료 | D10: - AI 위험평가 기준 설명 (작성내용 없음) | F10: -
B12: ■ 문서 버전관리
C14: 작성/수정일 | D14: 작성자(부서/성명) | E14: 주요 작성/수정 내용

Sheet 1. 영향&안전성 여부 판단서
D3: 영향&안전성 여부 판단서 | F3: AI 서비스기획
D4: YYYY.MM.DD
B6: 1. AI 서비스 위험/영향/안전성 판단 절차 개요
B12: 2. 고영향 및 안전성 대상 판단 조건
B24: ※ (고영향) 규정 2장 14조, 거버넌스운영지침 4장 26조 참조하여 판단
B25: ※ (안전성) 규정 2장 19조 참조하여 판단
B26: 필요 시, 하위법령 가이드라인 참고
B28: 3. 고영향 여부 체크리스트
B30: 그룹 | D30: 항목 | E30: 배점 | F30: 해당여부
B31: A | D31: 기존 모델보다 파라미터 증가, 학습 데이터 양 또는 유형의 확대 등으로 복잡도가 증가한 신규 모델에 기반한 인공지능시스템 | E31: 2
D32: 1만명 이상의 금융소비자를 대상으로 하는 인공지능시스템 | E32: 2
D33: 자동화 정도가 높고 속도가 빨라서 실질적으로 최종 의사결정에 관한 사람의 개입이 불가능한 인공지능시스템 | E33: 2
B34: B | D34: 대리 변수(Proxy Variable)1)를 활용하는 빈도가 높은 인공지능시스템 | E34: 1
D35: 특정 업무영역을 위해 개발 또는 고도화된 인공지능시스템을 다른 업무영역에 일시적으로 또는 단기간 활용하는 경우 | E35: 1
D36: 국외 데이터를 주로 학습하여 개발된 국외 인공지능시스템을 활용하는 경우 | E36: 1
B37: 최종점수 | F37: =SUMIFS($E$31:$E$36,$F$31:$F$36,"Yes") -> 0
B38: 고영향 AI 여부 | F38: =IF(AND(OR(COUNTIF($F$31:$F$33,"Yes")>=2,AND(COUNTIF($F$31:$F$33,"Yes")>=1,COUNTIF($F$34:$F$36,"Yes")>=2)),$F$37>=4),"Yes","No") -> No
B40: 1) 주요 변수를 조사하거나 파악하기 어려울 경우, 그와 상관관계가 높고 조사하기 용이하여 대신 사용할 수 있는 변수
B41: ※ A그룹 2개 항목 이상에 해당하거나 A그룹에 1개 및 B그룹에 2개에 해당하는 경우 ‘고영향 인공지능’에 해당됨
B43: 4. 안전성 여부 체크리스트
B45: 작성 가이드: 고영향 AI 해당 시 수행
B46: 1. [기획·설계 단계] 안전성 적용 대상 사전 판단
B47: 2. [개발 단계] 안전성 적용 대상 최종 판단
B49: No. | C49: 항목 | F49: 해당여부
B50: 1 | C50: 학습에 사용된 누적 연산량이 10^26 부동소수점연산(FLOPs, Floating Point Operations) 이상입니까?
B51: 2 | C51: 인공지능 발전 수준을 고려할 때 최첨단 인공지능기술을 적용하여 구성·운영되고 있습니까?
B52: 3 | C52: 사람의 생명·신체·기본권에 광범위하고 중대한 영향을 미칠 우려가 있습니까?
B53: 안전성 적용 대상 여부 | F53: =IF(AND($F$50="Yes",$F$51="Yes",$F$52="Yes"),"Yes","No") -> No
B55: ※ 본 보고서 양식 및 작성 내용은 AI거버넌스 업무지원을 위한 기본 서식으로, 필요 시 AI거버넌스 담당자와 사전협의를 통해 일부 수정할 수 있습니다.

Sheet 2. 위험 식별 및 평가
B2: ■ 위험 식별 및 평가 | F2: Yes/No | N2: 서비스기획 / 개발 담당자 수행 영역 | V2: 거버넌스 담당자 수행 영역
N3: 1. 서비스 선택 ▶ | P3: 1-1. 사용자범위: | Q3: 임직원 서비스 | R3: 대고객 서비스 / 임직원 서비스
B4: 고영향 AI 여부 | D4: Yes | P4: 1-2. 산출물특성: | R4: 생성형 / 판단형 / 복합형(생성형+판단형)
P5: 1-3. 의사결정영향도: | Q5: 인간결정형 (HITL) | R5: 인간결정형(HITL) / 인간감독형(HOTL) / 자율운영형(HOVL, HOUTL)
P6: 1-4. 데이터민감도: | R6: 비개인정보 / 개인정보 / 민감·신용정보
N8: 2. AI 위험 식별 | P8: 3. AI 위험 완화 방안 수립 | S8: 4. 잔여 AI 위험 평가 | V8: 5. 위험 평가 검토
B9: No. | C9: 위험(Lv1) | D9: 위험(Lv2) | E9: 위험(Lv3) | F9: 위험 정의 | G9: 위험 관리 부서 | H9: 위험 점수 | I9: 평가 방안 | J9: 완화방안 | K9: 평가 포함 여부 | L9: (필요시) 평가 포함 조정 | N9: 위험 식별 여부 | O9: (해당 시) 상세 위험 내용 (미해당 시) 위험 미해당 사유 | P9: 완화 방안 적용 여부 | Q9: 완화 방안 적용 계획 (상세) | R9: 완화 방안(예시) | S9: 완화방안 적용 시 위험 완화 정도 | T9: 최종 잔여 위험 | V9: 평가 수행 적정 여부 | W9: 상세 검토 의견
B10: 1 | C10: 합법성 원칙 | D10: 금융소비자보호법 위반 가능성 | E10: 고지 의무 위반 | F10: =VLOOKUP($E10,'AI 위험 정의 상세'!$D$6:$O$37,6,FALSE) -> 대고객 AI 서비스 운영 시 고지의무 대상 서비스에 대해서는 적합한 내용으로 고지 절차를 수행해야 하나 하지 않아서 제재를 받게 될 위험 (AI RMF 기준: 적합성/적정성 원칙, 불공정 영업행위 금지 원칙/상품 광고 규제) | G10: =VLOOKUP($E10,'AI 위험 정의 상세'!$D$6:$O$37,11,FALSE) -> AI 서비스기획 | H10: =VLOOKUP($E10,'AI 위험 정의 상세'!$D$6:$O$37,9,FALSE) -> 4 | I10: =VLOOKUP($E10,'AI 위험 정의 상세'!$D$6:$O$37,7,FALSE) -> § sLLM 기반 문구 적정성 검사(Content Validity): 법령에서 요구하는 필수 핵심 내용이 고지 문구에 포함되었는지 검사 § 자동화 로직: sLLM를 활용하여 고지 문구 내에 [AI 활용, 결과 도출 근거, 이의제기 권리, 담당부서 연락처] 등의 필수 키워드가 포함되어 있는지 확인 하나라도 누락 시 '주의' 등급을 부여 § 체크 리스트를 통한 사용자 판단 - 고지 절차 존재 및 고지 내용의 적정 여부 등 확인 | J10: =VLOOKUP($E10,'AI 위험 정의 상세'!$D$6:$O$37,8,FALSE) -> § 고지 절차 자동화 및 표준화: ITSM의 기획 단계에서 고지 의무 대상을 자동으로 식별하고, 표준화된 고지 템플릿을 서비스 설계에 반영하도록 강제화 § 관리시스템: 서비스 기획 및 AI 서비스 개발계획 수립 시 고지 항목을 정의하고 서비스 승인 절차에서 이행 여부를 최종 확정 § 평가시스템: 실제 운영 환경에서 고지 로그가 정상 적재되는지 모니터링하고, 검수+피드백 시스템을 통해 고지 문구의 개선 사항을 지속적으로 반영 | K10: =IF(OR(IFERROR(HLOOKUP($Q$3,'AI 위험 정의 상세'!$O$5:$Y$37,ROW(K10)-8,FALSE),"")="yes",IFERROR(HLOOKUP($Q$4,'AI 위험 정의 상세'!$O$5:$Y$37,ROW(K10)-8,FALSE),"")="yes",IFERROR(HLOOKUP($Q$5,'AI 위험 정의 상세'!$O$5:$Y$37,ROW(K10)-8,FALSE),"")="yes",IFERROR(HLOOKUP($Q$6,'AI 위험 정의 상세'!$O$5:$Y$37,ROW(K10)-8,FALSE),"")="yes"),"Yes","") -> Yes | P10: Yes | R10: =IF(P10="Yes",VLOOKUP($E10,'AI 위험 정의 상세'!$D$6:$O$37,8,FALSE),"") -> § 고지 절차 자동화 및 표준화: ITSM의 기획 단계에서 고지 의무 대상을 자동으로 식별하고, 표준화된 고지 템플릿을 서비스 설계에 반영하도록 강제화 § 관리시스템: 서비스 기획 및 AI 서비스 개발계획 수립 시 고지 항목을 정의하고 서비스 승인 절차에서 이행 여부를 최종 확정 § 평가시스템: 실제 운영 환경에서 고지 로그가 정상 적재되는지 모니터링하고, 검수+피드백 시스템을 통해 고지 문구의 개선 사항을 지속적으로 반영 | T10: {=_xlfn.IFS(AND(N10="Yes",P10="Yes"),H10*(1-VLOOKUP(S10,문구!$C$3:$D$7,2,FALSE)),AND(N10="Yes",OR(P10="No",P10="")),H10,TRUE,)} -> 0 | V10: No
B11: 2 | C11: 합법성 원칙 | D11: 금융소비자보호법 위반 가능성 | E11: 설명 의무/부당권유행위 위반 | F11: =VLOOKUP($E11,'AI 위험 정의 상세'!$D$6:$O$37,6,FALSE) -> 대고객 AI 서비스 운영 시 설명 의무 대상 서비스에 대해서는 설명 절차 수행해야 하나, 사전에 인지하지 못하거나 잘못된 정보를 제공할 위험 (AI RMF 기준: 설명의무/부당권유행위 금지 원칙) | G11: =VLOOKUP($E11,'AI 위험 정의 상세'!$D$6:$O$37,11,FALSE) -> AI 서비스기획 | H11: =VLOOKUP($E11,'AI 위험 정의 상세'!$D$6:$O$37,9,FALSE) -> 4 | I11: =VLOOKUP($E11,'AI 위험 정의 상세'!$D$6:$O$37,7,FALSE) -> § 설명 정합성 지수 (EA-Score): 로직: AI가 제시한 설명(Explanation)이 실제 모델의 피처 기여도(Feature Importance)와 얼마나 일치하는지 측정 기준: 정합성 98% 이상 '우수', 90% 미만 ‘주의'. § XAI 신뢰도 검증 (XF-Score): SHAP, LIME 등의 기술을 사용하여 모델의 판단 근거를 시각화하고, 이를 비즈니스 규칙과 대조하여 논리적 타당성을 검토 § 부당권유 탐지 모니터링: 특정 상품의 추천 빈도가 통계적으로 비정상적으로 높거나, 수익성 위주의 편향이 발견되는지 집단 간 격차 지수(DI)를 변형하여 측정 | J11: =VLOOKUP($E11,'AI 위험 정의 상세'!$D$6:$O$37,8,FALSE) -> § 관리시스템: AI 위험/영향 식별 단계에서 설명 의무 대상 여부를 판정하고, 위반 시 위험성 재평가 프로세스를 수행 § 평가시스템: RAG 기반 데이터 Faithful 점수평가를 통해 생성된 설명이 실제 규정집이나 데이터에 기반하고 있는지 실시간 검증 § 설명 가능한 AI(xAI) 워크플로우 의무화: 결정 결과와 함께 핵심 변수 3~5개를 소비자 화면에 자동으로 노출하는 기능을 설계 단계(ITSM)에서 필수화 | K11: =IF(OR(IFERROR(HLOOKUP($Q$3,'AI 위험 정의 상세'!$O$5:$Y$37,ROW(K11)-8,FALSE),"")="yes",IFERROR(HLOOKUP($Q$4,'AI 위험 정의 상세'!$O$5:$Y$37,ROW(K11)-8,FALSE),"")="yes",IFERROR(HLOOKUP($Q$5,'AI 위험 정의 상세'!$O$5:$Y$37,ROW(K11)-8,FALSE),"")="yes",IFERROR(HLOOKUP($Q$6,'AI 위험 정의 상세'!$O$5:$Y$37,ROW(K11)-8,FALSE),"")="yes"),"Yes","") -> Yes | N11: Yes | O11: 대고객 서비스이므로 설명 의무 확인 필요함 | P11: Yes | R11: =IF(P11="Yes",VLOOKUP($E11,'AI 위험 정의 상세'!$D$6:$O$37,8,FALSE),"") -> § 관리시스템: AI 위험/영향 식별 단계에서 설명 의무 대상 여부를 판정하고, 위반 시 위험성 재평가 프로세스를 수행 § 평가시스템: RAG 기반 데이터 Faithful 점수평가를 통해 생성된 설명이 실제 규정집이나 데이터에 기반하고 있는지 실시간 검증 § 설명 가능한 AI(xAI) 워크플로우 의무화: 결정 결과와 함께 핵심 변수 3~5개를 소비자 화면에 자동으로 노출하는 기능을 설계 단계(ITSM)에서 필수화 | S11: △ | T11: {=_xlfn.IFS(AND(N11="Yes",P11="Yes"),H11*(1-VLOOKUP(S11,문구!$C$3:$D$7,2,FALSE)),AND(N11="Yes",OR(P11="No",P11="")),H11,TRUE,)} -> 2 | V11: Yes
B12: 3 | C12: 합법성 원칙 | D12: AI기본법 위반 가능성 | E12: AI 기본법 위반 | F12: =VLOOKUP($E12,'AI 위험 정의 상세'!$D$6:$O$37,6,FALSE) -> AI 기본법의 주요 의무를 위반하거나 법령의 요구사항을 누락하여 서비스를 기획 및 운영할 위험 | G12: =VLOOKUP($E12,'AI 위험 정의 상세'!$D$6:$O$37,11,FALSE) -> AI 서비스기획 | H12: =VLOOKUP($E12,'AI 위험 정의 상세'!$D$6:$O$37,9,FALSE) -> 4 | I12: =VLOOKUP($E12,'AI 위험 정의 상세'!$D$6:$O$37,7,FALSE) -> § 법규 준수 진단 (Compliance Score) 로직: AI 기본법의 요구사항 기반 체크리스트 (예: 투명성 확보 의무에 따른 고지 의무 등)를 시스템화하여 이행 여부를 점수화 지표: 100점 만점 기준 100점 필수 (법적 의무 사항은 예외 없이 준수해야 함) § AI 영향 평가 (AIA, AI Impact Assessment): 관리시스템 내 'AI 위험/영향/안전성 식별/평가' 단계를 통해 해당 서비스가 인권, 안전, 사회적 가치에 미치는 영향을 사전에 분석 § 증적 완결성 검증: 법적 분쟁 시 제출할 수 있는 학습 데이터 출처, 알고리즘 설명서, 안전성 테스트 결과가 평가 이력 관리에 누락 없이 저장되어 있는지 자동 스캔 | J12: =VLOOKUP($E12,'AI 위험 정의 상세'!$D$6:$O$37,8,FALSE) -> § Legal-Tech 기반 가드레일: sLLM 기반 법령 스캐너를 활용하여 서비스 기획서 및 약관이 최신 AI 기본법 및 시행령에 부합하는지 실시간 검토 § 단계별 게이트키핑 (Gate-keeping): ITSM 워크플로우 상에서 법무/컴플라이언스 부서의 승인 없이는 모델 배포(Deployment)가 불가능하도록 시스템 통제장치를 설정 § 신뢰성 검인증 연계 : 제3자 인증 기관이나 국가 공인 신뢰성 검인증 지표를 평가시스템에 등록하고, 이를 통과한 모델만 운영할 수 있도록 관리 § 책임 소재의 명확화: 관리시스템 내에 각 AI 서비스별 'AI 관리책임자'를 명시하고, 생애주기별 R&R을 디지털 증적으로 남겨 책임성을 강화 | K12: =IF(OR(IFERROR(HLOOKUP($Q$3,'AI 위험 정의 상세'!$O$5:$Y$37,ROW(K12)-8,FALSE),"")="yes",IFERROR(HLOOKUP($Q$4,'AI 위험 정의 상세'!$O$5:$Y$37,ROW(K12)-8,FALSE),"")="yes",IFERROR(HLOOKUP($Q$5,'AI 위험 정의 상세'!$O$5:$Y$37,ROW(K12)-8,FALSE),"")="yes",IFERROR(HLOOKUP($Q$6,'AI 위험 정의 상세'!$O$5:$Y$37,ROW(K12)-8,FALSE),"")="yes"),"Yes","") -> Yes | N12: Yes | P12: No | R12: =IF(P12="Yes",VLOOKUP($E12,'AI 위험 정의 상세'!$D$6:$O$37,8,FALSE),"") | T12: {=_xlfn.IFS(AND(N12="Yes",P12="Yes"),H12*(1-VLOOKUP(S12,문구!$C$3:$D$7,2,FALSE)),AND(N12="Yes",OR(P12="No",P12="")),H12,TRUE,)} -> 4 | V12: No
B13: 4 | C13: 합법성 원칙 | D13: 데이터 관련법 위반 가능성 | E13: 민감 정보 추출/재식별 | F13: =VLOOKUP($E13,'AI 위험 정의 상세'!$D$6:$O$37,6,FALSE) -> AI의 추론 능력을 악용하여 개인의 민감 정보(건강, 위치 등)를 추출, 재식별, 연결, 추론함으로써 프라이버시 침해가 심화되고 개인 데이터가 악용 및 노출될 위험 | G13: =VLOOKUP($E13,'AI 위험 정의 상세'!$D$6:$O$37,11,FALSE) -> AI 서비스기획 | H13: =VLOOKUP($E13,'AI 위험 정의 상세'!$D$6:$O$37,9,FALSE) -> 2 | I13: =VLOOKUP($E13,'AI 위험 정의 상세'!$D$6:$O$37,7,FALSE) -> § 민감정보 생성 유발 레드티밍: 공격 프롬프트 생성을 자동화는 레드티밍 솔루션을 활용하여 민감정보 유출을 시도 - '공격 타입: <민감정보 유출> 설정 / 프롬프트: <공격 시나리오> 입력’으로 공격 시나리오 자동 생성 - 공격 성공 판단: 공격 시나리오 입/출력에 민감정보 포함 여부 - 위험 점수: (공격 성공 / 전체 공격 시도) X 100 | J13: =VLOOKUP($E13,'AI 위험 정의 상세'!$D$6:$O$37,8,FALSE) -> § 일반화 및 대체: 민감 데이터를 일반화하고 범주화하여 식별력을 낮춤 § 출력값 라운딩(Rounding) 및 제한: 모델 예측 확률을 정밀하게 주지 않고, 대략적인 범위로 제공 | K13: =IF(OR(IFERROR(HLOOKUP($Q$3,'AI 위험 정의 상세'!$O$5:$Y$37,ROW(K13)-8,FALSE),"")="yes",IFERROR(HLOOKUP($Q$4,'AI 위험 정의 상세'!$O$5:$Y$37,ROW(K13)-8,FALSE),"")="yes",IFERROR(HLOOKUP($Q$5,'AI 위험 정의 상세'!$O$5:$Y$37,ROW(K13)-8,FALSE),"")="yes",IFERROR(HLOOKUP($Q$6,'AI 위험 정의 상세'!$O$5:$Y$37,ROW(K13)-8,FALSE),"")="yes"),"Yes","") | N13: Yes | P13: Yes | R13: =IF(P13="Yes",VLOOKUP($E13,'AI 위험 정의 상세'!$D$6:$O$37,8,FALSE),"") -> § 일반화 및 대체: 민감 데이터를 일반화하고 범주화하여 식별력을 낮춤 § 출력값 라운딩(Rounding) 및 제한: 모델 예측 확률을 정밀하게 주지 않고, 대략적인 범위로 제공 | S13: ○ | T13: {=_xlfn.IFS(AND(N13="Yes",P13="Yes"),H13*(1-VLOOKUP(S13,문구!$C$3:$D$7,2,FALSE)),AND(N13="Yes",OR(P13="No",P13="")),H13,TRUE,)} -> 0 | V13: Yes
B14: 5 | C14: 합법성 원칙 | D14: 데이터 관련법 위반 가능성 | E14: 개인정보의 부적절한 처리 | F14: =VLOOKUP($E14,'AI 위험 정의 상세'!$D$6:$O$37,6,FALSE) -> 정보주체로부터 동의받지 않은 목적으로 모델 훈련에 사용 등 개인정보를 처리하거나 기타 데이터 사용, 이동, 판매에 관련한 법령을 위반할 위험 (개인정보보호법, 신용정보법, 위치정보법 등) | G14: =VLOOKUP($E14,'AI 위험 정의 상세'!$D$6:$O$37,11,FALSE) -> AI 서비스기획 | H14: =VLOOKUP($E14,'AI 위험 정의 상세'!$D$6:$O$37,9,FALSE) -> 2 | I14: =VLOOKUP($E14,'AI 위험 정의 상세'!$D$6:$O$37,7,FALSE) -> § 데이터 법령 준수 진단 (Compliance Score) - 로직: 개인정보법 및 신용정보법 상 요건 기반 체크리스트 (예: AI 학습 및 모델 개선 목적 개인정보 수집 이용 동의 징구 및 해당 데이터 한정 모델 학습 여부 등)를 시스템화하여 이행 여부를 점수화 - 지표: 100점 만점 기준 100점 필수 (법적 의무 사항은 예외 없이 준수해야 함) § 접근 로그 감사: 데이터 파이프라인 로그에 민감정보가 저장된 DB 테이블에 접근한 이력이 있는지 분석 - 공격 성공 판단: 데이터 파이프라인 로그에 민감정보에 접근한 이력이 있는 경우 - 위험 점수: 민감정보에 접근했는지 여부 | J14: =VLOOKUP($E14,'AI 위험 정의 상세'!$D$6:$O$37,8,FALSE) -> § AI 학습용 데이터 구분 동의: 수집 시점에 AI 학습용 데이터는 명확히 구분하여 동의를 획득하도록 UI 설계 § 민감정보 분리 보관: 민감정보는 물리적/논리적으로 완전히 분리된 별도 DB에 암호화하여 저장 | K14: =IF(OR(IFERROR(HLOOKUP($Q$3,'AI 위험 정의 상세'!$O$5:$Y$37,ROW(K14)-8,FALSE),"")="yes",IFERROR(HLOOKUP($Q$4,'AI 위험 정의 상세'!$O$5:$Y$37,ROW(K14)-8,FALSE),"")="yes",IFERROR(HLOOKUP($Q$5,'AI 위험 정의 상세'!$O$5:$Y$37,ROW(K14)-8,FALSE),"")="yes",IFERROR(HLOOKUP($Q$6,'AI 위험 정의 상세'!$O$5:$Y$37,ROW(K14)-8,FALSE),"")="yes"),"Yes","") | P14: No | R14: =IF(P14="Yes",VLOOKUP($E14,'AI 위험 정의 상세'!$D$6:$O$37,8,FALSE),"") | T14: {=_xlfn.IFS(AND(N14="Yes",P14="Yes"),H14*(1-VLOOKUP(S14,문구!$C$3:$D$7,2,FALSE)),AND(N14="Yes",OR(P14="No",P14="")),H14,TRUE,)} -> 0 | V14: No
B15: 6 | C15: 합법성 원칙 | D15: 개별 업권법 위반 가능성 | E15: 금융관련 법 위반 | F15: =VLOOKUP($E15,'AI 위험 정의 상세'!$D$6:$O$37,6,FALSE) -> AI 상품·서비스를 출시 및 운용하는 과정에서 자본시장법 등 개별 금융업권 법규를 위반할 수 있는 위험 | G15: =VLOOKUP($E15,'AI 위험 정의 상세'!$D$6:$O$37,11,FALSE) -> AI 서비스기획 | H15: =VLOOKUP($E15,'AI 위험 정의 상세'!$D$6:$O$37,9,FALSE) -> 4 | I15: =VLOOKUP($E15,'AI 위험 정의 상세'!$D$6:$O$37,7,FALSE) -> § 이상금융거래 탐지 시스템(FDS) 연동: AI 이용 방식이 법규 위반 패턴과 유사한지 판단 가능 - 공격 성공 판단: AI 상품 및 서비스 관련 요청 결과가 FDS에서 이상거래로 탐지 - 위험 점수 = (탐지 성공 / 전체 상품 및 서비스 관련 요청) X 100 § 법규 준수 진단 (Compliance Score) - 로직: 금융투자 관련 법령 상 요건 기반 체크리스트 (예: 자본시장법 제99조(투자일임보고서의 교부) 요구사항 등)를 시스템화하여 이행 여부를 점수화 - 지표: 100점 만점 기준 100점 필수 (법적 의무 사항은 예외 없이 준수해야 함) | J15: =VLOOKUP($E15,'AI 위험 정의 상세'!$D$6:$O$37,8,FALSE) -> § Human-In-the-Loop(HITL) 개념 적용: 잘못된 판단으로 고객에게 큰 손해가 발생하거나 위법 가능성 높은 상품이나 서비스는 마지막 단계에서 해당 근거를 설명하고 인간이 판단할 수 있도록 하는 프로세스 적용 § 진단 결과 발견 사항에 대한 개선 수행: 체크리스트를 통한 점검 결과 사전 발견한 미흡 사항을 확인하고 각 사항에 따른 완화 방안을 수립 및 이행하여, 금융 관련 법령을 준수하여 AI 서비스 및 시스템을 개발 및 운영 | K15: =IF(OR(IFERROR(HLOOKUP($Q$3,'AI 위험 정의 상세'!$O$5:$Y$37,ROW(K15)-8,FALSE),"")="yes",IFERROR(HLOOKUP($Q$4,'AI 위험 정의 상세'!$O$5:$Y$37,ROW(K15)-8,FALSE),"")="yes",IFERROR(HLOOKUP($Q$5,'AI 위험 정의 상세'!$O$5:$Y$37,ROW(K15)-8,FALSE),"")="yes",IFERROR(HLOOKUP($Q$6,'AI 위험 정의 상세'!$O$5:$Y$37,ROW(K15)-8,FALSE),"")="yes"),"Yes","") -> Yes | P15: No | R15: =IF(P15="Yes",VLOOKUP($E15,'AI 위험 정의 상세'!$D$6:$O$37,8,FALSE),"") | T15: {=_xlfn.IFS(AND(N15="Yes",P15="Yes"),H15*(1-VLOOKUP(S15,문구!$C$3:$D$7,2,FALSE)),AND(N15="Yes",OR(P15="No",P15="")),H15,TRUE,)} -> 0
B16: 7 | C16: 신뢰성 원칙 | D16: 품질 | E16: 데이터 불충분성 | F16: =VLOOKUP($E16,'AI 위험 정의 상세'!$D$6:$O$37,6,FALSE) -> 데이터셋이 AI 시스템의 상황 또는 의도된 사용을 정확하게 대표하지 못하거나, 실제 상황을 반영하지 못하여 AI 시스템의 신뢰성에 영향을 미칠 수 있는 위험 | G16: =VLOOKUP($E16,'AI 위험 정의 상세'!$D$6:$O$37,11,FALSE) -> AI 개발 | H16: =VLOOKUP($E16,'AI 위험 정의 상세'!$D$6:$O$37,9,FALSE) -> 2 | I16: =VLOOKUP($E16,'AI 위험 정의 상세'!$D$6:$O$37,7,FALSE) -> § 평가 지표: 신뢰구간(Confidence Interval, CI). § 판단 기준: 신뢰구간(CI) > 0.2인 경우, 예측 결과의 불확실성이 높은 것으로 간주하여 시스템 경고를 발생시키고 재학습 우선순위를 상향 조정 | J16: =VLOOKUP($E16,'AI 위험 정의 상세'!$D$6:$O$37,8,FALSE) -> § 능동적 학습(Active Learning) 기반 보강: 모델이 불확실하다고 판단하는 영역(CI > 0.2)의 데이터를 우선적으로 식별하여 집중적으로 수집하고 라벨링 § 데이터 증강(Data Augmentation): 합성 데이터 생성이나 통계적 오버샘플링을 통해 데이터가 희소한 구간을 보강하여 모델의 노출 빈도를 높힘 § 모델 기반 완화: 유사 도메인의 대규모 데이터를 활용한 전이 학습(Transfer Learning)을 적용하거나, 앙상블 기법을 통해 개별 모델의 불확실성을 상쇄 § 추론 제어 및 가드레일: 불확실성이 높은 예측 결과에 대해서는 AI의 독자적인 결정을 제한하고, 전문가(Human-in-the-Loop)의 개입을 요청하거나 사용자에게 불확실성을 사전에 고지 | K16: =IF(OR(IFERROR(HLOOKUP($Q$3,'AI 위험 정의 상세'!$O$5:$Y$37,ROW(K16)-8,FALSE),"")="yes",IFERROR(HLOOKUP($Q$4,'AI 위험 정의 상세'!$O$5:$Y$37,ROW(K16)-8,FALSE),"")="yes",IFERROR(HLOOKUP($Q$5,'AI 위험 정의 상세'!$O$5:$Y$37,ROW(K16)-8,FALSE),"")="yes",IFERROR(HLOOKUP($Q$6,'AI 위험 정의 상세'!$O$5:$Y$37,ROW(K16)-8,FALSE),"")="yes"),"Yes","") -> Yes | P16: =IF(N16="No","N/A","") | R16: =IF(P16="Yes",VLOOKUP($E16,'AI 위험 정의 상세'!$D$6:$O$37,8,FALSE),"") | T16: {=_xlfn.IFS(AND(N16="Yes",P16="Yes"),H16*(1-VLOOKUP(S16,문구!$C$3:$D$7,2,FALSE)),AND(N16="Yes",OR(P16="No",P16="")),H16,TRUE,)} -> 0
B17: 8 | C17: 신뢰성 원칙 | D17: 품질 | E17: 데이터 정확성 부족 | F17: =VLOOKUP($E17,'AI 위험 정의 상세'!$D$6:$O$37,6,FALSE) -> 모델 훈련에 사용되는 데이터가 실제 상황이나 사실을 정확하게 반영하지 못하거나 동일한 항목이 일관되지 않게 기록되어서 발생하는 위험 | G17: =VLOOKUP($E17,'AI 위험 정의 상세'!$D$6:$O$37,11,FALSE) -> AI 개발 | H17: =VLOOKUP($E17,'AI 위험 정의 상세'!$D$6:$O$37,9,FALSE) -> 2 | I17: =VLOOKUP($E17,'AI 위험 정의 상세'!$D$6:$O$37,7,FALSE) -> § 머신러닝 모델인 Isolation Forest를 학습시켜, "평균적인 데이터 분포에서 벗어난 정도"를 0~1 사이의 점수로 환산 § 수치 가이드: - 0.0 ~ 0.5: 정상 데이터. - 0.5 ~ 0.7: 단순 노이즈 가능성 (수정 권고). - 0.7 이상: 심각한 기록 오류 또는 조작 데이터 (삭제 필수). | J17: =VLOOKUP($E17,'AI 위험 정의 상세'!$D$6:$O$37,8,FALSE) -> § 이상치 점수 기반 자동 필터링 및 정제 (Cleaning) : 평가 시스템에서 도출된 Isolation Forest 점수를 기반으로 즉각적인 조치를 수행 § 데이터 입력 단계의 유효성 검증(Validation) 강화: 데이터가 시스템에 입력되는 시점에서 정확성을 확보하여 사후 정제 비용 축소 § MLOps 기반의 지속적 모니터링 및 재평가:데이터의 정확성은 시간에 따라 변할 수 있으므로 지속적인 관리 체계를 구축 § 거버넌스 및 전문 인력 검수 (Human-in-the-Loop):자동화된 시스템이 판별하기 어려운 맥락적 오류를 해결 | K17: =IF(OR(IFERROR(HLOOKUP($Q$3,'AI 위험 정의 상세'!$O$5:$Y$37,ROW(K17)-8,FALSE),"")="yes",IFERROR(HLOOKUP($Q$4,'AI 위험 정의 상세'!$O$5:$Y$37,ROW(K17)-8,FALSE),"")="yes",IFERROR(HLOOKUP($Q$5,'AI 위험 정의 상세'!$O$5:$Y$37,ROW(K17)-8,FALSE),"")="yes",IFERROR(HLOOKUP($Q$6,'AI 위험 정의 상세'!$O$5:$Y$37,ROW(K17)-8,FALSE),"")="yes"),"Yes","") -> Yes | P17: =IF(N17="No","N/A","") | R17: =IF(P17="Yes",VLOOKUP($E17,'AI 위험 정의 상세'!$D$6:$O$37,8,FALSE),"") | T17: {=_xlfn.IFS(AND(N17="Yes",P17="Yes"),H17*(1-VLOOKUP(S17,문구!$C$3:$D$7,2,FALSE)),AND(N17="Yes",OR(P17="No",P17="")),H17,TRUE,)} -> 0
B18: 9 | C18: 신뢰성 원칙 | D18: 품질 | E18: 학습 데이터 오염/손실 | F18: =VLOOKUP($E18,'AI 위험 정의 상세'!$D$6:$O$37,6,FALSE) -> 오염: 악의적인 목적으로 변조된 데이터(적대적 예제 또는 악의적인 노이즈)가 AI 모델 학습 시에 활용되어, AI 시스템의 성능 저하 및 오작동을 유발하는 공격 손실: 모델 훈련에 사용된 데이터가 절차 미흡이나 소홀, 기타 예상치 못한 사고로 인해 손실되어 모델을 재현할 수 없게 되는 위험 | G18: =VLOOKUP($E18,'AI 위험 정의 상세'!$D$6:$O$37,11,FALSE) -> AI 개발 | H18: =VLOOKUP($E18,'AI 위험 정의 상세'!$D$6:$O$37,9,FALSE) -> 2 | I18: =VLOOKUP($E18,'AI 위험 정의 상세'!$D$6:$O$37,7,FALSE) -> § 패킷 분석 툴(Fiddler 등) 이용: 패킷 분석 툴을 이용해서 특정 패킷의 이동을 멈춘 후 해당 패킷의 일부를 변조한 후, 전달하여 변조가 탐지되는지 확인 - 위험 점수: (변조 공격 성공 / 전체 변조 시도) X 100 | J18: =VLOOKUP($E18,'AI 위험 정의 상세'!$D$6:$O$37,8,FALSE) -> § 데이터 검증: 원본 배포처가 제공한 해시값(SHA-256)과 전달 받은 데이터의 해시값의 일치 여부로 오염/손실 확인 § 백업 저장소 잠금: 백업 저장소(Vault) 자체에 잠금을 걸어 공격자가 백업본을 삭제하지 못하도록 방어 | K18: =IF(OR(IFERROR(HLOOKUP($Q$3,'AI 위험 정의 상세'!$O$5:$Y$37,ROW(K18)-8,FALSE),"")="yes",IFERROR(HLOOKUP($Q$4,'AI 위험 정의 상세'!$O$5:$Y$37,ROW(K18)-8,FALSE),"")="yes",IFERROR(HLOOKUP($Q$5,'AI 위험 정의 상세'!$O$5:$Y$37,ROW(K18)-8,FALSE),"")="yes",IFERROR(HLOOKUP($Q$6,'AI 위험 정의 상세'!$O$5:$Y$37,ROW(K18)-8,FALSE),"")="yes"),"Yes","") -> Yes | P18: =IF(N18="No","N/A","") | R18: =IF(P18="Yes",VLOOKUP($E18,'AI 위험 정의 상세'!$D$6:$O$37,8,FALSE),"") | T18: {=_xlfn.IFS(AND(N18="Yes",P18="Yes"),H18*(1-VLOOKUP(S18,문구!$C$3:$D$7,2,FALSE)),AND(N18="Yes",OR(P18="No",P18="")),H18,TRUE,)} -> 0
B19: 10 | C19: 신뢰성 원칙 | D19: 편향성 | E19: 데이터 편향성 | F19: =VLOOKUP($E19,'AI 위험 정의 상세'!$D$6:$O$37,6,FALSE) -> 데이터셋 내의 직·간접적인 편향이 AI 시스템 결과에 영향을 미쳐 개인, 그룹 또는 사회에 불공정하거나 해로운 결과를 초래할 수 있는 위험 (인종·성별 등 인간 정체성 관련 편향 가능성 포함) | G19: =VLOOKUP($E19,'AI 위험 정의 상세'!$D$6:$O$37,11,FALSE) -> AI 개발 | H19: =VLOOKUP($E19,'AI 위험 정의 상세'!$D$6:$O$37,9,FALSE) -> 6 | I19: =VLOOKUP($E19,'AI 위험 정의 상세'!$D$6:$O$37,7,FALSE) -> § 편향 프롬프트 생성 레드티밍: 공격 프롬프트 생성을 자동화는 레드티밍 솔루션을 활용하여 편향된 프롬프트 생성 - 생성된 공격 프롬프트를 이용하여 반복적인 프롬프트 편향 결과를 유도하고 현재 AI 시스템이 안전한지 확인 및 통계 도출 가능 | J19: =VLOOKUP($E19,'AI 위험 정의 상세'!$D$6:$O$37,8,FALSE) -> § 편향 탐지 차단: 데이터 요청 중 편향성을 판단하여 차단하고 모니터링 (증오 / 괴롭힘 / 성적 콘텐츠 / 범죄 / 아동 성착취 / 자살 및 자해 등) | K19: =IF(OR(IFERROR(HLOOKUP($Q$3,'AI 위험 정의 상세'!$O$5:$Y$37,ROW(K19)-8,FALSE),"")="yes",IFERROR(HLOOKUP($Q$4,'AI 위험 정의 상세'!$O$5:$Y$37,ROW(K19)-8,FALSE),"")="yes",IFERROR(HLOOKUP($Q$5,'AI 위험 정의 상세'!$O$5:$Y$37,ROW(K19)-8,FALSE),"")="yes",IFERROR(HLOOKUP($Q$6,'AI 위험 정의 상세'!$O$5:$Y$37,ROW(K19)-8,FALSE),"")="yes"),"Yes","") -> Yes | P19: =IF(N19="No","N/A","") | R19: =IF(P19="Yes",VLOOKUP($E19,'AI 위험 정의 상세'!$D$6:$O$37,8,FALSE),"") | T19: {=_xlfn.IFS(AND(N19="Yes",P19="Yes"),H19*(1-VLOOKUP(S19,문구!$C$3:$D$7,2,FALSE)),AND(N19="Yes",OR(P19="No",P19="")),H19,TRUE,)} -> 0
B20: 11 | C20: 신뢰성 원칙 | D20: 공정성 | E20: 공정성 위반 | F20: =VLOOKUP($E20,'AI 위험 정의 상세'!$D$6:$O$37,6,FALSE) -> 모델을 훈련시키는데 사용되는 데이터가 전체 고객이나 상황을 대표하지 못하고 모델의 구조나 알고리즘의 특성에 따라 특정 데이터 또는 입력값에 대해 편향된 결과를 산출하는 위험 | G20: =VLOOKUP($E20,'AI 위험 정의 상세'!$D$6:$O$37,11,FALSE) -> AI 개발 | H20: =VLOOKUP($E20,'AI 위험 정의 상세'!$D$6:$O$37,9,FALSE) -> 6 | I20: =VLOOKUP($E20,'AI 위험 정의 상세'!$D$6:$O$37,7,FALSE) -> § 집단 간 격차 지수 : DI-Index (Disparate Impact) - 산식: (소수/취약 집단의 승인율) / (다수 집단의 승인율) - 0.8 ≤ DI ≤ 1.25: 우수. 범위 이탈 시: 주의 | J20: =VLOOKUP($E20,'AI 위험 정의 상세'!$D$6:$O$37,8,FALSE) -> § 공정성 보정 알고리즘 적용: 모델 학습 단계에서 공정성 제약 조건(Fairness Constraints)을 추가하거나, 모델 출력 단계에서 임계값을 조정하여 집단 간 승인율 격차를 강제로 보정. § 설명 가능성(XAI) 강화: 차별적 결과가 의심되는 시나리오에 대해 SHAP나 LIME 등의 기술을 활용하여 결정 근거가 비즈니스 논리에 부합하는지 전수 검증 § 데이터 리샘플링: 특정 집단의 데이터가 부족하여 편향이 발생한 경우, 오버샘플링(Oversampling)이나 가중치 조정을 통해 학습 데이터의 균형 준수 § 관리 시스템 기반 워크플로우: DI 지수가 0.8 미만 또는 1.25 초과 시 시스템이 경고를 발생시키고, 모델 배포 전 전문가의 '공정성 승인' 절차를 거치도록 통제 | K20: =IF(OR(IFERROR(HLOOKUP($Q$3,'AI 위험 정의 상세'!$O$5:$Y$37,ROW(K20)-8,FALSE),"")="yes",IFERROR(HLOOKUP($Q$4,'AI 위험 정의 상세'!$O$5:$Y$37,ROW(K20)-8,FALSE),"")="yes",IFERROR(HLOOKUP($Q$5,'AI 위험 정의 상세'!$O$5:$Y$37,ROW(K20)-8,FALSE),"")="yes",IFERROR(HLOOKUP($Q$6,'AI 위험 정의 상세'!$O$5:$Y$37,ROW(K20)-8,FALSE),"")="yes"),"Yes","") -> Yes | P20: =IF(N20="No","N/A","") | R20: =IF(P20="Yes",VLOOKUP($E20,'AI 위험 정의 상세'!$D$6:$O$37,8,FALSE),"") | T20: {=_xlfn.IFS(AND(N20="Yes",P20="Yes"),H20*(1-VLOOKUP(S20,문구!$C$3:$D$7,2,FALSE)),AND(N20="Yes",OR(P20="No",P20="")),H20,TRUE,)} -> 0
B21: 12 | C21: 신뢰성 원칙 | D21: 설명가능성 | E21: 설명 가능성/투명성 부족 | F21: =VLOOKUP($E21,'AI 위험 정의 상세'!$D$6:$O$37,6,FALSE) -> AI 시스템 작동의 기본 메커니즘을 나타내는 '설명 가능성'과 시스템의 결과가 시스템과 상호작용하는 개인에게 제공되는 '투명성'이 부족하여 책임 소재 결정이나 디버깅이 어려운 위험 | G21: =VLOOKUP($E21,'AI 위험 정의 상세'!$D$6:$O$37,11,FALSE) -> AI 서비스기획 | H21: =VLOOKUP($E21,'AI 위험 정의 상세'!$D$6:$O$37,9,FALSE) -> 6 | I21: =VLOOKUP($E21,'AI 위험 정의 상세'!$D$6:$O$37,7,FALSE) -> § XAI 충실도 점수 (Faithfulness Score): - 산식: 설명 모델(SHAP 등)이 제시한 중요도와 실제 모델의 입력값 변화에 따른 출력값 변화의 상관계수를 측정. - 지표: 0.9 이상일 때 설명의 신뢰도가 높다고 판단 | J21: =VLOOKUP($E21,'AI 위험 정의 상세'!$D$6:$O$37,8,FALSE) -> § 설명 가능한 AI(XAI) 기술 도입: 모델 설계 시 SHAP, LIME, Grad-CAM 등 시각화 도구를 통합하여 모델의 판단 근거를 실시간으로 추출 § 모델 카드(Model Cards) 의무화: 관리시스템 내 '평가 이력 관리' 모듈에 모델의 용도, 한계점, 학습 데이터 특성, 성능 지표 등을 표준화된 문서 형식으로 기록하고 공개 § 투명한 인터페이스 설계: 사용자에게 결과만 전달하는 것이 아니라, "귀하의 점수가 낮은 이유는 최근 3개월간의 연체 기록이 60%의 비중으로 영향을 미쳤기 때문입니다"와 같은 구체적인 근거를 UI/UX에 반영 § 추적 가능성(Traceability) 확보: 모든 의사결정 로그를 관리시스템에 저장하여, 사후 감사나 디버깅 시 해당 시점의 입력 데이터와 모델 파라미터를 즉시 복원할 수 있는 체계를 구축 | K21: =IF(OR(IFERROR(HLOOKUP($Q$3,'AI 위험 정의 상세'!$O$5:$Y$37,ROW(K21)-8,FALSE),"")="yes",IFERROR(HLOOKUP($Q$4,'AI 위험 정의 상세'!$O$5:$Y$37,ROW(K21)-8,FALSE),"")="yes",IFERROR(HLOOKUP($Q$5,'AI 위험 정의 상세'!$O$5:$Y$37,ROW(K21)-8,FALSE),"")="yes",IFERROR(HLOOKUP($Q$6,'AI 위험 정의 상세'!$O$5:$Y$37,ROW(K21)-8,FALSE),"")="yes"),"Yes","") -> Yes | P21: =IF(N21="No","N/A","") | R21: =IF(P21="Yes",VLOOKUP($E21,'AI 위험 정의 상세'!$D$6:$O$37,8,FALSE),"") | T21: {=_xlfn.IFS(AND(N21="Yes",P21="Yes"),H21*(1-VLOOKUP(S21,문구!$C$3:$D$7,2,FALSE)),AND(N21="Yes",OR(P21="No",P21="")),H21,TRUE,)} -> 0
B22: 13 | C22: 신뢰성 원칙 | D22: 성능 | E22: 모델 과대/과소 적합 위험 | F22: =VLOOKUP($E22,'AI 위험 정의 상세'!$D$6:$O$37,6,FALSE) -> 과대적합: 모델이 학습 데이터에 지나치게 적합되어 있어서 새로운 데이터의 입력에 대해서 일반화할 수 있는 결과를 산출하지 못하는 위험 과소적합: 모델이 학습 데이터의 부족으로 충분히 테스트하기 어렵거나 하지 않아서 일반화를 하지 못하고 실제 환경에서 예상하지 못한 성능저하가 발생하는 위험 | G22: =VLOOKUP($E22,'AI 위험 정의 상세'!$D$6:$O$37,11,FALSE) -> AI 개발 | H22: =VLOOKUP($E22,'AI 위험 정의 상세'!$D$6:$O$37,9,FALSE) -> 1 | I22: =VLOOKUP($E22,'AI 위험 정의 상세'!$D$6:$O$37,7,FALSE) -> § 학습/검증 손실 곡선 분석 (Learning Curve): 학습 데이터의 손실(Loss)과 검증 데이터의 손실 간 격차를 모니터링. -과대적합 판정: 학습 손실은 지속적으로 감소하나 검증 손실이 증가하기 시작할 때. -과소적합 판정: 학습과 검증 손실 모두 높은 수준에서 정체될 때. § 성능 유지율 모니터링: 운영 중 유입되는 실제 데이터에 대한 성능 유지율을 정기적으로 측정하여 배포 초기 성능 대비 급격한 하락 여부를 확인. § 통계적 구간 추정 (Uncertainty Estimation): 데이터 양이 모델의 일반화 성능을 보장하는지 신뢰구간(CI)을 통해 수치화 - 신뢰구간(CI) > 0.2일 경우 불확실성 경고를 발생 | J22: =VLOOKUP($E22,'AI 위험 정의 상세'!$D$6:$O$37,8,FALSE) -> § 과대적합 완화 - 규제화(Regularization) 적용: L1, L2 규제 등을 적용하여 특정 가중치가 지나치게 커지지 않도록 제어 - 조기 종료(Early Stopping): 검증 손실이 더 이상 개선되지 않는 시점에서 학습을 자동으로 중단 - 데이터 증강(Data Augmentation): 학습 데이터의 양을 늘리고 변동성을 주어 모델이 특정 패턴에 고착이 되지 않도록 함 § 과소적합 완화 - 모델 복잡도 상향: 더 많은 층(Layer)이나 파라미터를 가진 모델로 구조를 변경하여 데이터의 복잡한 패턴을 학습 - 데이터 보강 및 능동적 학습(Active Learning): 데이터가 부족한 영역을 식별하여 추가 데이터를 수집하고 학습에 반영 - 특징 엔지니어링(Feature Engineering): 예측에 유의미한 변수를 추가 발굴하여 모델의 학습 효율 제고 | K22: =IF(OR(IFERROR(HLOOKUP($Q$3,'AI 위험 정의 상세'!$O$5:$Y$37,ROW(K22)-8,FALSE),"")="yes",IFERROR(HLOOKUP($Q$4,'AI 위험 정의 상세'!$O$5:$Y$37,ROW(K22)-8,FALSE),"")="yes",IFERROR(HLOOKUP($Q$5,'AI 위험 정의 상세'!$O$5:$Y$37,ROW(K22)-8,FALSE),"")="yes",IFERROR(HLOOKUP($Q$6,'AI 위험 정의 상세'!$O$5:$Y$37,ROW(K22)-8,FALSE),"")="yes"),"Yes","") -> Yes | P22: =IF(N22="No","N/A","") | R22: =IF(P22="Yes",VLOOKUP($E22,'AI 위험 정의 상세'!$D$6:$O$37,8,FALSE),"") | T22: {=_xlfn.IFS(AND(N22="Yes",P22="Yes"),H22*(1-VLOOKUP(S22,문구!$C$3:$D$7,2,FALSE)),AND(N22="Yes",OR(P22="No",P22="")),H22,TRUE,)} -> 0
B23: 14 | C23: 신뢰성 원칙 | D23: 성능 | E23: 모델 드리프트 위험 | F23: =VLOOKUP($E23,'AI 위험 정의 상세'!$D$6:$O$37,6,FALSE) -> 모델이 개발된 상당 시간이 경과함에 따라 당초에 학습했던 데이터 환경과 예측하는 데이터의 분포 변화에 따라 예측 성능 저하가 발생하는 위험 | G23: =VLOOKUP($E23,'AI 위험 정의 상세'!$D$6:$O$37,11,FALSE) -> AI 개발 | H23: =VLOOKUP($E23,'AI 위험 정의 상세'!$D$6:$O$37,9,FALSE) -> 1 | I23: =VLOOKUP($E23,'AI 위험 정의 상세'!$D$6:$O$37,7,FALSE) -> § 인구통계적 안정성 지수(PSI, Population Stability Index): 학습 데이터와 운영 데이터의 분포 차이를 수치화하여 관리. - 0.1 미만: 분포 변화 적음 (정상) - 0.1 ~ 0.25: 유의미한 변화 발생 (주의) - 0.25 초과: 급격한 분포 변화 (위험, 재학습 필요) § 통계적 검정(K-S Test): 두 데이터 분포가 동일한 모집단에서 추출되었는지 확인하기 위해 Kolmogorov-Smirnov 검정 등을 수행 § 성능 지표 모니터링: 실제 운영 데이터에 대한 정확도(Accuracy), 정밀도(Precision), F1-score 등의 지표가 초기 배포 대비 급격히 하락하는지 상시 트래킹 | J23: =VLOOKUP($E23,'AI 위험 정의 상세'!$D$6:$O$37,8,FALSE) -> § 모델 재학습(Retraining): 최신 운영 데이터를 포함하여 모델을 다시 학습시킴으로써 변화된 데이터 환경을 반영 § 데이터 가중치 조정: 최신 데이터에 더 높은 가중치를 부여하여 학습함으로써 모델이 최신 트렌드에 민첩하게 반응 § 챔피언-챌린저(Champion-Challenger) 테스트: 기존 모델(Champion)과 최신 데이터로 학습된 신규 모델(Challenger)을 동시 운영하여 성능을 비교 검증한 후 교체 § 자동화 파이프라인(MLOps) 구축: 드리프트가 특정 임계치(예: PSI > 0.25)를 넘어서면 자동으로 재학습 및 평가가 이뤄지도록 '검수+피드백 시스템'을 연결 | K23: =IF(OR(IFERROR(HLOOKUP($Q$3,'AI 위험 정의 상세'!$O$5:$Y$37,ROW(K23)-8,FALSE),"")="yes",IFERROR(HLOOKUP($Q$4,'AI 위험 정의 상세'!$O$5:$Y$37,ROW(K23)-8,FALSE),"")="yes",IFERROR(HLOOKUP($Q$5,'AI 위험 정의 상세'!$O$5:$Y$37,ROW(K23)-8,FALSE),"")="yes",IFERROR(HLOOKUP($Q$6,'AI 위험 정의 상세'!$O$5:$Y$37,ROW(K23)-8,FALSE),"")="yes"),"Yes","") -> Yes | P23: =IF(N23="No","N/A","") | R23: =IF(P23="Yes",VLOOKUP($E23,'AI 위험 정의 상세'!$D$6:$O$37,8,FALSE),"") | T23: {=_xlfn.IFS(AND(N23="Yes",P23="Yes"),H23*(1-VLOOKUP(S23,문구!$C$3:$D$7,2,FALSE)),AND(N23="Yes",OR(P23="No",P23="")),H23,TRUE,)} -> 0
B24: 15 | C24: 신뢰성 원칙 | D24: 성능 | E24: 모델 붕괴 (Model Collapse) | F24: =VLOOKUP($E24,'AI 위험 정의 상세'!$D$6:$O$37,6,FALSE) -> 학습 데이터의 고갈 및 AI가 생성한 합성 데이터가 재학습에 반복적으로 활용되면서, AI 모델의 성능이 급격히 저하되거나 오류가 계속 쌓이는 현상 | G24: =VLOOKUP($E24,'AI 위험 정의 상세'!$D$6:$O$37,11,FALSE) -> AI 개발 | H24: =VLOOKUP($E24,'AI 위험 정의 상세'!$D$6:$O$37,9,FALSE) -> 1 | I24: =VLOOKUP($E24,'AI 위험 정의 상세'!$D$6:$O$37,7,FALSE) -> § 데이터 다양성 지수 (Diversity Index): 학습 데이터셋 내의 어휘 다양성이나 데이터 분포의 엔트로피를 측정하여, 합성 데이터 유입으로 인해 분포가 단순화되고 있는지 감시 § 성능 유지율 및 오차 누적 측정: 동일한 벤치마크 테스트셋에 대해 모델 버전별 성능 변화를 추적하여 성능이 급격히 꺾이는 지점을 탐지 § 합성 데이터 혼합비 추적: 전체 학습 데이터 중 AI가 생성한 데이터(Dsynthetic )의 비중을 정량적으로 관리 | J24: =VLOOKUP($E24,'AI 위험 정의 상세'!$D$6:$O$37,8,FALSE) -> § 원본 데이터(Human-generated) 보존 및 우선순위 상향: 모델 재학습 시 AI 생성 데이터보다 인간이 직접 작성한 고품질 원본 데이터의 비중을 높게 유지 § 데이터 워터마크 및 출처 추적: AI가 생성한 데이터에 워터마크를 삽입하거나 메타데이터를 관리하여, 재학습 시 합성 데이터가 무분별하게 섞이지 않도록 필터링. § 검수+피드백 시스템 강화: AI 생성 데이터 중 품질이 검증된 데이터만 학습에 포함될 수 있도록 전문가가 개입하는 검수 단계를 표준화 § 안전 가드레일 설정: 모델 붕괴 조짐이 보일 경우, 이전 세대의 안정적인 모델(Golden Model)로 롤백하거나 성능 저하 원인을 분석하여 데이터 클렌징 재수행 § 평가시스템: RAG 기반 데이터 Faithful 점수평가 및 LLM 기반의 평가 모듈을 활용하여 데이터의 진위 여부와 품질을 스캔하여 붕괴 위험 점수를 도출 § 관리시스템: 도출된 점수를 바탕으로 수시 위험성 체크를 수행하며, 위험 점수가 높을 경우 서비스 오픈 승인을 보류하고 데이터 정제 단계로 회수 | K24: =IF(OR(IFERROR(HLOOKUP($Q$3,'AI 위험 정의 상세'!$O$5:$Y$37,ROW(K24)-8,FALSE),"")="yes",IFERROR(HLOOKUP($Q$4,'AI 위험 정의 상세'!$O$5:$Y$37,ROW(K24)-8,FALSE),"")="yes",IFERROR(HLOOKUP($Q$5,'AI 위험 정의 상세'!$O$5:$Y$37,ROW(K24)-8,FALSE),"")="yes",IFERROR(HLOOKUP($Q$6,'AI 위험 정의 상세'!$O$5:$Y$37,ROW(K24)-8,FALSE),"")="yes"),"Yes","") -> Yes | P24: =IF(N24="No","N/A","") | R24: =IF(P24="Yes",VLOOKUP($E24,'AI 위험 정의 상세'!$D$6:$O$37,8,FALSE),"") | T24: {=_xlfn.IFS(AND(N24="Yes",P24="Yes"),H24*(1-VLOOKUP(S24,문구!$C$3:$D$7,2,FALSE)),AND(N24="Yes",OR(P24="No",P24="")),H24,TRUE,)} -> 0
B25: 16 | C25: 신뢰성 원칙 | D25: 성능 | E25: 모델 성능 지표 부적합 | F25: =VLOOKUP($E25,'AI 위험 정의 상세'!$D$6:$O$37,6,FALSE) -> 모델의 성능을 평가할 적절한 성능지표가 없거나 부적절한 지표가 선택되어 성능관리가 어려워질 위험 | G25: =VLOOKUP($E25,'AI 위험 정의 상세'!$D$6:$O$37,11,FALSE) -> AI 서비스기획 | H25: =VLOOKUP($E25,'AI 위험 정의 상세'!$D$6:$O$37,9,FALSE) -> 1 | I25: =VLOOKUP($E25,'AI 위험 정의 상세'!$D$6:$O$37,7,FALSE) -> § 다차원 지표 매트릭스 활용: 단일 지표가 아닌 혼동 행렬(Confusion Matrix)을 기반으로 정밀도(Precision), 재현율(Recall), F1-Score, AUC-ROC 등을 종합적으로 산출하여 지표 간 상충 관계를 분석 § 통계적 구간 추정 (U-Score): 선택된 지표가 통계적으로 유의미한지 확인하기 위해 신뢰구간을 산출합니다. 신뢰구간(CI) > 0.2인 경우, 선택된 지표의 신뢰도가 낮다고 판단하고 경고를 발생 § 지표 적합성 체크리스트: 모델의 유형(분류, 회귀, 생성 등)과 데이터의 특성(불균형성 등)에 비추어 표준 가이드라인에 맞는 지표가 선택되었는지 시스템적으로 대조 | J25: =VLOOKUP($E25,'AI 위험 정의 상세'!$D$6:$O$37,8,FALSE) -> § 비즈니스 맞춤형 지표 재정의: 서비스 기획 단계에서 정의한 핵심 성과 지표(KPI)와 모델 지표를 매핑하여, 비즈니스 손실과 직결되는 지표(예: 비용 가중치 적용 F-beta score)를 재설정 § 검수 및 피드백 시스템 연계: 평가시스템에서 산출된 다차원 지표 결과를 전문가가 검수하여, 특정 지표에 편향된 성능 측정이 이루어지지 않았는지 확인하고 피드백 § 지표 가이드라인 표준화: 조직 내 'AI 성능 지표 표준 가이드'를 수립하고, 관리시스템의 평가항목 관리 기능에 등록하여 일관된 평가 기준을 적용 § 수시 위험성 체크: 모델 운영 중에도 선택된 지표가 실제 소비자 보호나 비즈니스 가치를 잘 대변하고 있는지 주기적으로 모니터링하고 필요시 지표를 변경 | K25: =IF(OR(IFERROR(HLOOKUP($Q$3,'AI 위험 정의 상세'!$O$5:$Y$37,ROW(K25)-8,FALSE),"")="yes",IFERROR(HLOOKUP($Q$4,'AI 위험 정의 상세'!$O$5:$Y$37,ROW(K25)-8,FALSE),"")="yes",IFERROR(HLOOKUP($Q$5,'AI 위험 정의 상세'!$O$5:$Y$37,ROW(K25)-8,FALSE),"")="yes",IFERROR(HLOOKUP($Q$6,'AI 위험 정의 상세'!$O$5:$Y$37,ROW(K25)-8,FALSE),"")="yes"),"Yes","") -> Yes | P25: =IF(N25="No","N/A","") | R25: =IF(P25="Yes",VLOOKUP($E25,'AI 위험 정의 상세'!$D$6:$O$37,8,FALSE),"") | T25: {=_xlfn.IFS(AND(N25="Yes",P25="Yes"),H25*(1-VLOOKUP(S25,문구!$C$3:$D$7,2,FALSE)),AND(N25="Yes",OR(P25="No",P25="")),H25,TRUE,)} -> 0
B26: 17 | C26: 신뢰성 원칙 | D26: 성능 | E26: 부정확한 정보 출력 (환각) | F26: =VLOOKUP($E26,'AI 위험 정의 상세'!$D$6:$O$37,6,FALSE) -> AI 모델의 결과물이 정확한 것처럼 생성되었으나 실제로는 거짓이거나 오류가 있는 콘텐츠(환각, 작화)를 제작하여 사용자를 오도하거나 기만할 위험 | G26: =VLOOKUP($E26,'AI 위험 정의 상세'!$D$6:$O$37,11,FALSE) -> AI 서비스기획 | H26: =VLOOKUP($E26,'AI 위험 정의 상세'!$D$6:$O$37,9,FALSE) -> 2 | I26: =VLOOKUP($E26,'AI 위험 정의 상세'!$D$6:$O$37,7,FALSE) -> § 충실도 점수(Faithfulness Score): 생성된 답변이 제공된 소스 데이터(Source)에 기반하고 있는지 문장 단위로 대조하여 근거 일치율을 계산 § 답변 일관성 테스트(Self-Consistency): 동일한 질문에 대해 모델이 반복적으로 상이한 정보를 출력하는지 확인하여 정보의 안정성을 평가 § LLM-as-a-Judge: 고성능의 외부 LLM을 평가자로 활용하여, 생성된 답변의 사실 관계(Fact-checking)를 검증하고 환각 점수를 산출 | J26: =VLOOKUP($E26,'AI 위험 정의 상세'!$D$6:$O$37,8,FALSE) -> § 평가시스템: RAG 기반 데이터 Faithful 점수평가 엔진이 실시간으로 답변의 근거 유무를 판단하여 환각 지수를 도출 § 관리시스템: 환각 위험 점수가 임계치를 초과할 경우 수시 위험성 체크 단계에서 경고를 발생시키고, 모델 배포 전 성능 검증 및 기획 설계 수정을 유도 § RAG(검색 증강 생성) 최적화: 외부 지식 베이스(Knowledge Base)를 연동하여 모델이 학습 데이터에만 의존하지 않고 최신 실측 자료(Ground Truth)를 바탕으로 답변하도록 설계 § 자기 반추(Self-Correction) 워크플로우: 모델이 답변을 생성한 후 스스로 오류가 없는지 다시 한번 검토하고 수정하는 단계를 추가 § 신뢰성 경고 및 근거 노출: 답변과 함께 참고한 소스 문서의 출처(Citation)를 명시하여 사용자가 직접 사실 여부를 판단할 수 있도록 지원 § 프롬프트 엔지니어링 및 가드레일: "모르는 내용은 모른다고 답하라"는 페르소나를 부여하거나, 답변 생성 전후에 사실 검증 필터링을 수행하는 가드레일 시스템을 구축 | K26: =IF(OR(IFERROR(HLOOKUP($Q$3,'AI 위험 정의 상세'!$O$5:$Y$37,ROW(K26)-8,FALSE),"")="yes",IFERROR(HLOOKUP($Q$4,'AI 위험 정의 상세'!$O$5:$Y$37,ROW(K26)-8,FALSE),"")="yes",IFERROR(HLOOKUP($Q$5,'AI 위험 정의 상세'!$O$5:$Y$37,ROW(K26)-8,FALSE),"")="yes",IFERROR(HLOOKUP($Q$6,'AI 위험 정의 상세'!$O$5:$Y$37,ROW(K26)-8,FALSE),"")="yes"),"Yes","") -> Yes | P26: =IF(N26="No","N/A","") | R26: =IF(P26="Yes",VLOOKUP($E26,'AI 위험 정의 상세'!$D$6:$O$37,8,FALSE),"") | T26: {=_xlfn.IFS(AND(N26="Yes",P26="Yes"),H26*(1-VLOOKUP(S26,문구!$C$3:$D$7,2,FALSE)),AND(N26="Yes",OR(P26="No",P26="")),H26,TRUE,)} -> 0
B27: 18 | C27: 신의성실의 원칙 | D27: 계약 권리 침해 | E27: 의사결정 기능 오작동 | F27: =VLOOKUP($E27,'AI 위험 정의 상세'!$D$6:$O$37,6,FALSE) -> AI 모델 또는 시스템 기능에 대한 오해, 부적절한 지침 등으로 인해 AI가 의도하지 않은 방향으로 작동하여 실질적인 피해를 유발하거나, 전문 분야에서 심각한 오류가 발생하는 위험 (예: AI의 의사결정으로 인해 금전적 피해가 발생하거나, 고객의 금융거래 계약 조건 등에 영향을 미쳐 자유로운 권리행사를 저해) | G27: =VLOOKUP($E27,'AI 위험 정의 상세'!$D$6:$O$37,11,FALSE) -> AI 서비스기획 | H27: =VLOOKUP($E27,'AI 위험 정의 상세'!$D$6:$O$37,9,FALSE) -> 6 | I27: =VLOOKUP($E27,'AI 위험 정의 상세'!$D$6:$O$37,7,FALSE) -> § 시나리오 기반 회귀 테스트: 금융거래 계약 등 주요 의사결정 상황에 대해 사전에 정의된 테스트 시나리오를 반복 수행하여 의도된 결과가 도출되는지 확인 § 해석 가능한 모델(XAI) 평가: AI가 특정 의사결정을 내린 근거(피처 기여도 등)를 분석하여, 그 판단 로직이 타당하고 설명 가능한지 평가 § RAG 기반 데이터 Faithful 점수평가: AI가 내린 결정이 실제 비즈니스 가이드라인이나 지식 베이스(Knowledge Base)에 충실한지 정량적으로 점수화 § 집단 간 격차 지수(DI) 분석: 의사결정 결과가 특정 고객층에게 불리하게 작동하여 권리 행사를 저해하고 있지는 않은지 통계적으로 검증 | J27: =VLOOKUP($E27,'AI 위험 정의 상세'!$D$6:$O$37,8,FALSE) -> § 관리시스템: 기획 단계에서 AI 위험/영향/안전성 식별/평가를 통해 의사결정 오작동이 발생할 수 있는 주요 접점을 미리 파악하고 통제 계획을 수립 § 평가시스템: 실제 개발된 서비스가 모델 평가 및 데이터 평가 과정을 통과하여 수치화된 안전 점수를 획득했는지 확인 § 검수+피드백 시스템: 오작동 사례를 데이터화하여 지속적으로 평가시스템에 피드백함으로써 시스템의 판단 정확도를 고도화 § Human-in-the-Loop(전문가 개입): 금전적 피해나 계약 조건에 직접적인 영향을 주는 고위험 의사결정 시나리오의 경우, 최종 결정 전에 전문가의 승인을 거치도록 시스템적으로 강제 | K27: =IF(OR(IFERROR(HLOOKUP($Q$3,'AI 위험 정의 상세'!$O$5:$Y$37,ROW(K27)-8,FALSE),"")="yes",IFERROR(HLOOKUP($Q$4,'AI 위험 정의 상세'!$O$5:$Y$37,ROW(K27)-8,FALSE),"")="yes",IFERROR(HLOOKUP($Q$5,'AI 위험 정의 상세'!$O$5:$Y$37,ROW(K27)-8,FALSE),"")="yes",IFERROR(HLOOKUP($Q$6,'AI 위험 정의 상세'!$O$5:$Y$37,ROW(K27)-8,FALSE),"")="yes"),"Yes","") -> Yes | P27: =IF(N27="No","N/A","") | R27: =IF(P27="Yes",VLOOKUP($E27,'AI 위험 정의 상세'!$D$6:$O$37,8,FALSE),"") | T27: {=_xlfn.IFS(AND(N27="Yes",P27="Yes"),H27*(1-VLOOKUP(S27,문구!$C$3:$D$7,2,FALSE)),AND(N27="Yes",OR(P27="No",P27="")),H27,TRUE,)} -> 0
... B41: 32 | C41: 보안성 원칙 | D41: 프라이버시 | E41: 필요 이상 데이터 수집 | F41: =VLOOKUP($E41,'AI 위험 정의 상세'!$D$6:$O$37,6,FALSE) -> AI 서비스가 운영되면서 필요 이상으로 사용자 데이터를 수집하거나 감시하여 프라이버시를 침해할 위험 | G41: =VLOOKUP($E41,'AI 위험 정의 상세'!$D$6:$O$37,11,FALSE) -> AI 서비스기획 | H41: =VLOOKUP($E41,'AI 위험 정의 상세'!$D$6:$O$37,9,FALSE) -> 2 | I41: =VLOOKUP($E41,'AI 위험 정의 상세'!$D$6:$O$37,7,FALSE) -> § 데이터 최소화 원칙(Data Minimization) 준수 점검: 수집 중인 데이터 항목이 서비스의 목적달성에 필수적인지 여부를 체크리스트 기반으로 평가하여 준수 지수(Compliance Score)를 산출 § 개인정보 영향평가(DPIA) 연동: 관리시스템 내의 'AI 위험/영향/안성성 식별/평가' 단계에서 데이터 수집이 프라이버시에 미치는 영향을 사전에 수치화 § 데이터 생명주기 모니터링: 수집된 데이터의 보관 기간, 파기 절차, 접근 권한 관리 현황을 정기적으로 감사하여 평가 이력 관리 모듈에 기록 | J41: =VLOOKUP($E41,'AI 위험 정의 상세'!$D$6:$O$37,8,FALSE) -> § 관리시스템: 서비스 기획 및 AI 서비스 개발계획 단계에서 데이터 수집 범위를 확정하고 승인 절차 수행 § 평가시스템: 실제 운영 중 수집되는 데이터가 승인된 항목과 일치하는지 기술적으로 검증하고, 초과 수집 발생 시 관리자에게 즉시 알림을 발송 | K41: =IF(OR(IFERROR(HLOOKUP($Q$3,'AI 위험 정의 상세'!$O$5:$Y$37,ROW(K41)-8,FALSE),"")="yes",IFERROR(HLOOKUP($Q$4,'AI 위험 정의 상세'!$O$5:$Y$37,ROW(K41)-8,FALSE),"")="yes",IFERROR(HLOOKUP($Q$5,'AI 위험 정의 상세'!$O$5:$Y$37,ROW(K41)-8,FALSE),"")="yes",IFERROR(HLOOKUP($Q$6,'AI 위험 정의 상세'!$O$5:$Y$37,ROW(K41)-8,FALSE),"")="yes"),"Yes","") -> Yes | P41: =IF(N41="No","N/A","") | R41: =IF(P41="Yes",VLOOKUP($E41,'AI 위험 정의 상세'!$D$6:$O$37,8,FALSE),"") | T41: {=_xlfn.IFS(AND(N41="Yes",P41="Yes"),H41*(1-VLOOKUP(S41,문구!$C$3:$D$7,2,FALSE)),AND(N41="Yes",OR(P41="No",P41="")),H41,TRUE,)} -> 0
K50: =COUNTIF($K$10:$K$41,"Yes") -> 25 | N50: =IF(COUNTIFS($K10:$K41,"Yes",$N$10:$N$41,"")>0,"미완료","완료") -> 미완료 | P50: {=_xlfn.IFS(N50="미완료","미완료",COUNTIFS($K10:$K41,"Yes",$N$10:$N$41,"yes",$P$10:$P$41,"")>0,"미완료",TRUE,"완료")} -> 미완료 | S50: {=_xlfn.IFS(P50="미완료","미완료",COUNTIFS($K10:$K41,"Yes",$N$10:$N$41,"yes",$P$10:$P$41,"yes",$S$10:$S$41,"")>0,"미완료",TRUE,"완료")} -> 미완료 | T50: =SUM(T10:T41) -> 6 | V50: {=_xlfn.IFS(S50="미완료","미완료",COUNTIFS($K10:$K41,"Yes",$N$10:$N$41,"yes",$P$10:$P$41,"yes",$S$10:$S$41,"")>0,"미완료",TRUE,"완료")} -> 미완료

Sheet 3. AI 위험 평가 보고서
C3: AI 서비스 위험등급 평가서 | F3: AI 서비스기획
C4: YYYY.MM.DD
B6: ■ AI서비스명 : ///
B8: ■ 항목별 위험 점수 합산
B9: 위험(Lv1) | C9: 문항 수 | D9: 영역 총점 | E9: 위험 점수
E10: 인식 위험 점수 | F10: 잔여 위험 점수
B11: 합법성 원칙 | C11: ='평가 결과(요약)'!D12 -> 4 | D11: ='평가 결과(요약)'!E12 -> 16 | E11: ='평가 결과(요약)'!G12 -> 10 | F11: ='평가 결과(요약)'!I12 -> 2
B12: 신뢰성 원칙 | C12: ='평가 결과(요약)'!D18 -> 11 | D12: ='평가 결과(요약)'!E18 -> 30 | E12: ='평가 결과(요약)'!G18 -> 0 | F12: ='평가 결과(요약)'!I18 -> 0
B13: 신의성실의 원칙 | C13: ='평가 결과(요약)'!D22 -> 1 | D13: ='평가 결과(요약)'!E22 -> 6 | E13: ='평가 결과(요약)'!G22 -> 0 | F13: ='평가 결과(요약)'!I22 -> 0
B14: 보안성 원칙 | C14: ='평가 결과(요약)'!D27 -> 7 | D14: ='평가 결과(요약)'!E27 -> 16 | E14: ='평가 결과(요약)'!G27 -> 0 | F14: ='평가 결과(요약)'!I27 -> 0
B15: 합계 | C15: =SUM(C11:C14) -> 23 | D15: =SUM(D11:D14) -> 68 | E15: =SUM(E11:E14) -> 10 | F15: =SUM(F11:F14) -> 2
B17: ■ 서비스 위험 등급 확정
B18: 서비스 위험 점수 | D18: 서비스 위험 등급
B19: =F15 -> 2 | D19: {=_xlfn.IFS('2. 위험 식별 및 평가'!N50="미완료","위험 식별 중",'2. 위험 식별 및 평가'!P50="미완료","완화 방안 수립 중",'2. 위험 식별 및 평가'!S50="미완료","잔여 위험 평가 중",'2. 위험 식별 및 평가'!V50="미완료","위험 평가 검토중",B19>='AI 위험평가 기준자료'!C14,'AI 위험평가 기준자료'!B14,OR('2. 위험 식별 및 평가'!D4="yes",B19>'AI 위험평가 기준자료'!C15),'AI 위험평가 기준자료'!B15,B19>='AI 위험평가 기준자료'!C16,'AI 위험평가 기준자료'!B16,TRUE,'AI 위험평가 기준자료'!B17)} -> 위험 식별 중
B21: ■ 검토자
B22: 담당 구분 | C22: AI 서비스기획 | D22: AI 개발 | E22: AI 거버넌스
B24: 부서명
B25: 담당자
B27: [참고] 위험 등급 기준
B28: 위험수준 | C28: 하단 | E28: 상단
B29: 허용불가 서비스 | C29: ='AI 위험평가 기준자료'!C14 -> 75 | E29: ='AI 위험평가 기준자료'!D14 -> 100
B30: 고위험 서비스 | C30: ='AI 위험평가 기준자료'!C15 -> 50 | E30: ='AI 위험평가 기준자료'!D15 -> 74
B31: 중위험 서비스 | C31: ='AI 위험평가 기준자료'!C16 -> 25 | E31: ='AI 위험평가 기준자료'!D16 -> 49
B32: 저위험 서비스 | C32: ='AI 위험평가 기준자료'!C17 -> 0 | E32: ='AI 위험평가 기준자료'!D17 -> 24

Sheet 평가 결과(요약)
B2: ■ 위험 평가 결과 요약 (※ 자동 업데이트 됨, 작성 불필요)
B3: 위험 점수 | C3: =I28 -> 2
B4: 평가 수행 결과 (기획/개발) | C4: {=_xlfn.IFS('2. 위험 식별 및 평가'!S50="미완료","평가 수행 중",C3>='AI 위험평가 기준자료'!C14,'AI 위험평가 기준자료'!B14,OR('2. 위험 식별 및 평가'!D4="Yes",C3>'AI 위험평가 기준자료'!C15),'AI 위험평가 기준자료'!B15,C3>='AI 위험평가 기준자료'!C16,'AI 위험평가 기준자료'!B16,TRUE,'AI 위험평가 기준자료'!B17)} -> 평가 수행 중
B5: 평가 검토 결과 (거버넌스) | C5: {=_xlfn.IFS(C4="평가 수행 중","평가 대기 중",'2. 위험 식별 및 평가'!V50="미완료","평가 검토 중",AND('2. 위험 식별 및 평가'!V50="완료",COUNTIF('2. 위험 식별 및 평가'!V10:V41,"No")=0),"검토 완료",AND('2. 위험 식별 및 평가'!V50="완료",COUNTIF('2. 위험 식별 및 평가'!V10:V41,"no")>0,COUNTIF('2. 위험 식별 및 평가'!K10:K41,"<>")=COUNTIFS('2. 위험 식별 및 평가'!K10:K41,"yes",'2. 위험 식별 및 평가'!V10:V41,"<>0")),"재평가 필요",TRUE,"평가 시트 내 평가 제외 위험항목의 Z열 삭제 필요")} -> 평가 대기 중
B7: 위험(Lv1) | C7: 위험(Lv2) | D7: 평가 대상 위험 개수 | E7: 평가 대상 위험 점수 | F7: 식별 위험 개수 (Lv3) | G7: 식별 위험 점수 (Lv3) | H7: 잔여 위험 개수 (Lv3) | I7: 잔여 위험 점수 (Lv3)
B8: 합법성 원칙 | C8: 금융소비자보호법 위반 가능성 | D8: =COUNTIFS('2. 위험 식별 및 평가'!$D$10:$D$41,C8,'2. 위험 식별 및 평가'!$K$10:$K$41,"Yes") -> 2 | E8: =SUMIFS('2. 위험 식별 및 평가'!$H$10:$H$41,'2. 위험 식별 및 평가'!$D$10:$D$41,'평가 결과(요약)'!C8,'2. 위험 식별 및 평가'!$K$10:$K$41,"yes") -> 8 | F8: =COUNTIFS('2. 위험 식별 및 평가'!$D$10:$D$41,C8,'2. 위험 식별 및 평가'!$N$10:$N$41,"Yes") -> 1 | G8: =SUMIFS('2. 위험 식별 및 평가'!$H$10:$H$41,'2. 위험 식별 및 평가'!$D$10:$D$41,'평가 결과(요약)'!C8,'2. 위험 식별 및 평가'!$N$10:$N$41,"yes") -> 4 | H8: =COUNTIFS('2. 위험 식별 및 평가'!$D$10:$D$41,C8,'2. 위험 식별 및 평가'!$T$10:$T$41,">0") -> 1 | I8: =SUMIF('2. 위험 식별 및 평가'!$D$10:$D$41,'평가 결과(요약)'!C8,'2. 위험 식별 및 평가'!$T$10:$T$41) -> 2
B9: 합법성 원칙 | C9: AI기본법 위반 가능성 | D9: =COUNTIFS('2. 위험 식별 및 평가'!$D$10:$D$41,C9,'2. 위험 식별 및 평가'!$K$10:$K$41,"Yes") -> 1 | E9: =SUMIFS('2. 위험 식별 및 평가'!$H$10:$H$41,'2. 위험 식별 및 평가'!$D$10:$D$41,'평가 결과(요약)'!C9,'2. 위험 식별 및 평가'!$K$10:$K$41,"yes") -> 4 | F9: =COUNTIFS('2. 위험 식별 및 평가'!$D$10:$D$41,C9,'2. 위험 식별 및 평가'!$N$10:$N$41,"Yes") -> 1 | G9: =SUMIFS('2. 위험 식별 및 평가'!$H$10:$H$41,'2. 위험 식별 및 평가'!$D$10:$D$41,'평가 결과(요약)'!C9,'2. 위험 식별 및 평가'!$N$10:$N$41,"yes") -> 4 | H9: =COUNTIFS('2. 위험 식별 및 평가'!$D$10:$D$41,C9,'2. 위험 식별 및 평가'!$T$10:$T$41,">0") -> 1 | I9: =SUMIF('3. 잔여 AI 위험 평가'!$D$7:$D$38,'평가 결과(요약)'!C9,'3. 잔여 AI 위험 평가'!$T$7:$T$38) -> 0
B10: 합법성 원칙 | C10: 데이터 관련법 위반 가능성 | D10: =COUNTIFS('2. 위험 식별 및 평가'!$D$10:$D$41,C10,'2. 위험 식별 및 평가'!$K$10:$K$41,"Yes") -> 0 | E10: =SUMIFS('2. 위험 식별 및 평가'!$H$10:$H$41,'2. 위험 식별 및 평가'!$D$10:$D$41,'평가 결과(요약)'!C10,'2. 위험 식별 및 평가'!$K$10:$K$41,"yes") -> 0 | F10: =COUNTIFS('2. 위험 식별 및 평가'!$D$10:$D$41,C10,'2. 위험 식별 및 평가'!$N$10:$N$41,"Yes") -> 1 | G10: =SUMIFS('2. 위험 식별 및 평가'!$H$10:$H$41,'2. 위험 식별 및 평가'!$D$10:$D$41,'평가 결과(요약)'!C10,'2. 위험 식별 및 평가'!$N$10:$N$41,"yes") -> 2 | H10: =COUNTIFS('2. 위험 식별 및 평가'!$D$10:$D$41,C10,'2. 위험 식별 및 평가'!$T$10:$T$41,">0") -> 0 | I10: =SUMIF('3. 잔여 AI 위험 평가'!$D$7:$D$38,'평가 결과(요약)'!C10,'3. 잔여 AI 위험 평가'!$T$7:$T$38) -> 0
B11: 합법성 원칙 | C11: 개별 업권법 위반 가능성 | D11: =COUNTIFS('2. 위험 식별 및 평가'!$D$10:$D$41,C11,'2. 위험 식별 및 평가'!$K$10:$K$41,"Yes") -> 1 | E11: =SUMIFS('2. 위험 식별 및 평가'!$H$10:$H$41,'2. 위험 식별 및 평가'!$D$10:$D$41,'평가 결과(요약)'!C11,'2. 위험 식별 및 평가'!$K$10:$K$41,"yes") -> 4 | F11: =COUNTIFS('2. 위험 식별 및 평가'!$D$10:$D$41,C11,'2. 위험 식별 및 평가'!$N$10:$N$41,"Yes") -> 0 | G11: =SUMIFS('2. 위험 식별 및 평가'!$H$10:$H$41,'2. 위험 식별 및 평가'!$D$10:$D$41,'평가 결과(요약)'!C11,'2. 위험 식별 및 평가'!$N$10:$N$41,"yes") -> 0 | H11: =COUNTIFS('2. 위험 식별 및 평가'!$D$10:$D$41,C11,'2. 위험 식별 및 평가'!$T$10:$T$41,">0") -> 0 | I11: =SUMIF('3. 잔여 AI 위험 평가'!$D$7:$D$38,'평가 결과(요약)'!C11,'3. 잔여 AI 위험 평가'!$T$7:$T$38) -> 0
B12: =B11&" 합계" -> 합법성 원칙 합계 | D12: =SUBTOTAL(9,D8:D11) -> 4 | E12: =SUBTOTAL(9,E8:E11) -> 16 | F12: =SUBTOTAL(9,F8:F11) -> 3 | G12: =SUBTOTAL(9,G8:G11) -> 10 | H12: =SUBTOTAL(9,H8:H11) -> 2 | I12: =SUBTOTAL(9,I8:I11) -> 2
B13: 신뢰성 원칙 | C13: 품질 | D13: =COUNTIFS('2. 위험 식별 및 평가'!$D$10:$D$41,C13,'2. 위험 식별 및 평가'!$K$10:$K$41,"Yes") -> 3 | E13: =SUMIFS('2. 위험 식별 및 평가'!$H$10:$H$41,'2. 위험 식별 및 평가'!$D$10:$D$41,'평가 결과(요약)'!C13,'2. 위험 식별 및 평가'!$K$10:$K$41,"yes") -> 6 | F13: =COUNTIFS('2. 위험 식별 및 평가'!$D$10:$D$41,C13,'2. 위험 식별 및 평가'!$N$10:$N$41,"Yes") -> 0 | G13: =SUMIFS('2. 위험 식별 및 평가'!$H$10:$H$41,'2. 위험 식별 및 평가'!$D$10:$D$41,'평가 결과(요약)'!C13,'2. 위험 식별 및 평가'!$N$10:$N$41,"yes") -> 0 | H13: =COUNTIFS('2. 위험 식별 및 평가'!$D$10:$D$41,C13,'2. 위험 식별 및 평가'!$T$10:$T$41,">0") -> 0 | I13: =SUMIF('3. 잔여 AI 위험 평가'!$D$7:$D$38,'평가 결과(요약)'!C13,'3. 잔여 AI 위험 평가'!$T$7:$T$38) -> 0
B14: 신뢰성 원칙 | C14: 편향성 | D14: =COUNTIFS('2. 위험 식별 및 평가'!$D$10:$D$41,C14,'2. 위험 식별 및 평가'!$K$10:$K$41,"Yes") -> 1 | E14: =SUMIFS('2. 위험 식별 및 평가'!$H$10:$H$41,'2. 위험 식별 및 평가'!$D$10:$D$41,'평가 결과(요약)'!C14,'2. 위험 식별 및 평가'!$K$10:$K$41,"yes") -> 6 | F14: =COUNTIFS('2. 위험 식별 및 평가'!$D$10:$D$41,C14,'2. 위험 식별 및 평가'!$N$10:$N$41,"Yes") -> 0 | G14: =SUMIFS('2. 위험 식별 및 평가'!$H$10:$H$41,'2. 위험 식별 및 평가'!$D$10:$D$41,'평가 결과(요약)'!C14,'2. 위험 식별 및 평가'!$N$10:$N$41,"yes") -> 0 | H14: =COUNTIFS('2. 위험 식별 및 평가'!$D$10:$D$41,C14,'2. 위험 식별 및 평가'!$T$10:$T$41,">0") -> 0 | I14: =SUMIF('3. 잔여 AI 위험 평가'!$D$7:$D$38,'평가 결과(요약)'!C14,'3. 잔여 AI 위험 평가'!$T$7:$T$38) -> 0
B15: 신뢰성 원칙 | C15: 공정성 | D15: =COUNTIFS('2. 위험 식별 및 평가'!$D$10:$D$41,C15,'2. 위험 식별 및 평가'!$K$10:$K$41,"Yes") -> 1 | E15: =SUMIFS('2. 위험 식별 및 평가'!$H$10:$H$41,'2. 위험 식별 및 평가'!$D$10:$D$41,'평가 결과(요약)'!C15,'2. 위험 식별 및 평가'!$K$10:$K$41,"yes") -> 6 | F15: =COUNTIFS('2. 위험 식별 및 평가'!$D$10:$D$41,C15,'2. 위험 식별 및 평가'!$N$10:$N$41,"Yes") -> 0 | G15: =SUMIFS('2. 위험 식별 및 평가'!$H$10:$H$41,'2. 위험 식별 및 평가'!$D$10:$D$41,'평가 결과(요약)'!C15,'2. 위험 식별 및 평가'!$N$10:$N$41,"yes") -> 0 | H15: =COUNTIFS('2. 위험 식별 및 평가'!$D$10:$D$41,C15,'2. 위험 식별 및 평가'!$T$10:$T$41,">0") -> 0 | I15: =SUMIF('3. 잔여 AI 위험 평가'!$D$7:$D$38,'평가 결과(요약)'!C15,'3. 잔여 AI 위험 평가'!$T$7:$T$38) -> 0
B16: 신뢰성 원칙 | C16: 설명가능성 | D16: =COUNTIFS('2. 위험 식별 및 평가'!$D$10:$D$41,C16,'2. 위험 식별 및 평가'!$K$10:$K$41,"Yes") -> 1 | E16: =SUMIFS('2. 위험 식별 및 평가'!$H$10:$H$41,'2. 위험 식별 및 평가'!$D$10:$D$41,'평가 결과(요약)'!C16,'2. 위험 식별 및 평가'!$K$10:$K$41,"yes") -> 6 | F16: =COUNTIFS('2. 위험 식별 및 평가'!$D$10:$D$41,C16,'2. 위험 식별 및 평가'!$N$10:$N$41,"Yes") -> 0 | G16: =SUMIFS('2. 위험 식별 및 평가'!$H$10:$H$41,'2. 위험 식별 및 평가'!$D$10:$D$41,'평가 결과(요약)'!C16,'2. 위험 식별 및 평가'!$N$10:$N$41,"yes") -> 0 | H16: =COUNTIFS('2. 위험 식별 및 평가'!$D$10:$D$41,C16,'2. 위험 식별 및 평가'!$T$10:$T$41,">0") -> 0 | I16: =SUMIF('3. 잔여 AI 위험 평가'!$D$7:$D$38,'평가 결과(요약)'!C16,'3. 잔여 AI 위험 평가'!$T$7:$T$38) -> 0
B17: 신뢰성 원칙 | C17: 성능 | D17: =COUNTIFS('2. 위험 식별 및 평가'!$D$10:$D$41,C17,'2. 위험 식별 및 평가'!$K$10:$K$41,"Yes") -> 5 | E17: =SUMIFS('2. 위험 식별 및 평가'!$H$10:$H$41,'2. 위험 식별 및 평가'!$D$10:$D$41,'평가 결과(요약)'!C17,'2. 위험 식별 및 평가'!$K$10:$K$41,"yes") -> 6 | F17: =COUNTIFS('2. 위험 식별 및 평가'!$D$10:$D$41,C17,'2. 위험 식별 및 평가'!$N$10:$N$41,"Yes") -> 0 | G17: =SUMIFS('2. 위험 식별 및 평가'!$H$10:$H$41,'2. 위험 식별 및 평가'!$D$10:$D$41,'평가 결과(요약)'!C17,'2. 위험 식별 및 평가'!$N$10:$N$41,"yes") -> 0 | H17: =COUNTIFS('2. 위험 식별 및 평가'!$D$10:$D$41,C17,'2. 위험 식별 및 평가'!$T$10:$T$41,">0") -> 0 | I17: =SUMIF('3. 잔여 AI 위험 평가'!$D$7:$D$38,'평가 결과(요약)'!C17,'3. 잔여 AI 위험 평가'!$T$7:$T$38) -> 0
B18: =B17&" 합계" -> 신뢰성 원칙 합계 | D18: =SUBTOTAL(9,D13:D17) -> 11 | E18: =SUBTOTAL(9,E13:E17) -> 30 | F18: =SUBTOTAL(9,F13:F17) -> 0 | G18: =SUBTOTAL(9,G13:G17) -> 0 | H18: =SUBTOTAL(9,H13:H17) -> 0 | I18: =SUBTOTAL(9,I13:I17) -> 0
B19: 신의성실의 원칙 | C19: 계약 권리 침해 | D19: =COUNTIFS('2. 위험 식별 및 평가'!$D$10:$D$41,C19,'2. 위험 식별 및 평가'!$K$10:$K$41,"Yes") -> 1 | E19: =SUMIFS('2. 위험 식별 및 평가'!$H$10:$H$41,'2. 위험 식별 및 평가'!$D$10:$D$41,'평가 결과(요약)'!C19,'2. 위험 식별 및 평가'!$K$10:$K$41,"yes") -> 6 | F19: =COUNTIFS('2. 위험 식별 및 평가'!$D$10:$D$41,C19,'2. 위험 식별 및 평가'!$N$10:$N$41,"Yes") -> 0 | G19: =SUMIFS('2. 위험 식별 및 평가'!$H$10:$H$41,'2. 위험 식별 및 평가'!$D$10:$D$41,'평가 결과(요약)'!C19,'2. 위험 식별 및 평가'!$N$10:$N$41,"yes") -> 0 | H19: =COUNTIFS('2. 위험 식별 및 평가'!$D$10:$D$41,C19,'2. 위험 식별 및 평가'!$T$10:$T$41,">0") -> 0 | I19: =SUMIF('3. 잔여 AI 위험 평가'!$D$7:$D$38,'평가 결과(요약)'!C19,'3. 잔여 AI 위험 평가'!$T$7:$T$38) -> 0
B20: 신의성실의 원칙 | C20: 책임 투명성 | D20: =COUNTIFS('2. 위험 식별 및 평가'!$D$10:$D$41,C20,'2. 위험 식별 및 평가'!$K$10:$K$41,"Yes") -> 0 | E20: =SUMIFS('2. 위험 식별 및 평가'!$H$10:$H$41,'2. 위험 식별 및 평가'!$D$10:$D$41,'평가 결과(요약)'!C20,'2. 위험 식별 및 평가'!$K$10:$K$41,"yes") -> 0 | F20: =COUNTIFS('2. 위험 식별 및 평가'!$D$10:$D$41,C20,'2. 위험 식별 및 평가'!$N$10:$N$41,"Yes") -> 0 | G20: =SUMIFS('2. 위험 식별 및 평가'!$H$10:$H$41,'2. 위험 식별 및 평가'!$D$10:$D$41,'평가 결과(요약)'!C20,'2. 위험 식별 및 평가'!$N$10:$N$41,"yes") -> 0 | H20: =COUNTIFS('2. 위험 식별 및 평가'!$D$10:$D$41,C20,'2. 위험 식별 및 평가'!$T$10:$T$41,">0") -> 0 | I20: =SUMIF('3. 잔여 AI 위험 평가'!$D$7:$D$38,'평가 결과(요약)'!C20,'3. 잔여 AI 위험 평가'!$T$7:$T$38) -> 0
B21: 신의성실의 원칙 | C21: 소비자 보호방안 | D21: =COUNTIFS('2. 위험 식별 및 평가'!$D$10:$D$41,C21,'2. 위험 식별 및 평가'!$K$10:$K$41,"Yes") -> 0 | E21: =SUMIFS('2. 위험 식별 및 평가'!$H$10:$H$41,'2. 위험 식별 및 평가'!$D$10:$D$41,'평가 결과(요약)'!C21,'2. 위험 식별 및 평가'!$K$10:$K$41,"yes") -> 0 | F21: =COUNTIFS('2. 위험 식별 및 평가'!$D$10:$D$41,C21,'2. 위험 식별 및 평가'!$N$10:$N$41,"Yes") -> 0 | G21: =SUMIFS('2. 위험 식별 및 평가'!$H$10:$H$41,'2. 위험 식별 및 평가'!$D$10:$D$41,'평가 결과(요약)'!C21,'2. 위험 식별 및 평가'!$N$10:$N$41,"yes") -> 0 | H21: =COUNTIFS('2. 위험 식별 및 평가'!$D$10:$D$41,C21,'2. 위험 식별 및 평가'!$T$10:$T$41,">0") -> 0 | I21: =SUMIF('3. 잔여 AI 위험 평가'!$D$7:$D$38,'평가 결과(요약)'!C21,'3. 잔여 AI 위험 평가'!$T$7:$T$38) -> 0
B22: =B21&" 합계" -> 신의성실의 원칙 합계 | D22: =SUBTOTAL(9,D19:D21) -> 1 | E22: =SUBTOTAL(9,E19:E21) -> 6 | F22: =SUBTOTAL(9,F19:F21) -> 0 | G22: =SUBTOTAL(9,G19:G21) -> 0 | H22: =SUBTOTAL(9,H19:H21) -> 0 | I22: =SUBTOTAL(9,I19:I21) -> 0
B23: 보안성 원칙 | C23: 보안 | D23: =COUNTIFS('2. 위험 식별 및 평가'!$D$10:$D$41,C23,'2. 위험 식별 및 평가'!$K$10:$K$41,"Yes") -> 4 | E23: =SUMIFS('2. 위험 식별 및 평가'!$H$10:$H$41,'2. 위험 식별 및 평가'!$D$10:$D$41,'평가 결과(요약)'!C23,'2. 위험 식별 및 평가'!$K$10:$K$41,"yes") -> 8 | F23: =COUNTIFS('2. 위험 식별 및 평가'!$D$10:$D$41,C23,'2. 위험 식별 및 평가'!$N$10:$N$41,"Yes") -> 0 | G23: =SUMIFS('2. 위험 식별 및 평가'!$H$10:$H$41,'2. 위험 식별 및 평가'!$D$10:$D$41,'평가 결과(요약)'!C23,'2. 위험 식별 및 평가'!$N$10:$N$41,"yes") -> 0 | H23: =COUNTIFS('2. 위험 식별 및 평가'!$D$10:$D$41,C23,'2. 위험 식별 및 평가'!$T$10:$T$41,">0") -> 0 | I23: =SUMIF('3. 잔여 AI 위험 평가'!$D$7:$D$38,'평가 결과(요약)'!C23,'3. 잔여 AI 위험 평가'!$T$7:$T$38) -> 0
B24: 보안성 원칙 | C24: 안정성 | D24: =COUNTIFS('2. 위험 식별 및 평가'!$D$10:$D$41,C24,'2. 위험 식별 및 평가'!$K$10:$K$41,"Yes") -> 0 | E24: =SUMIFS('2. 위험 식별 및 평가'!$H$10:$H$41,'2. 위험 식별 및 평가'!$D$10:$D$41,'평가 결과(요약)'!C24,'2. 위험 식별 및 평가'!$K$10:$K$41,"yes") -> 0 | F24: =COUNTIFS('2. 위험 식별 및 평가'!$D$10:$D$41,C24,'2. 위험 식별 및 평가'!$N$10:$N$41,"Yes") -> 0 | G24: =SUMIFS('2. 위험 식별 및 평가'!$H$10:$H$41,'2. 위험 식별 및 평가'!$D$10:$D$41,'평가 결과(요약)'!C24,'2. 위험 식별 및 평가'!$N$10:$N$41,"yes") -> 0 | H24: =COUNTIFS('2. 위험 식별 및 평가'!$D$10:$D$41,C24,'2. 위험 식별 및 평가'!$T$10:$T$41,">0") -> 0 | I24: =SUMIF('3. 잔여 AI 위험 평가'!$D$7:$D$38,'평가 결과(요약)'!C24,'3. 잔여 AI 위험 평가'!$T$7:$T$38) -> 0
B25: 보안성 원칙 | C25: 위탁/관리 | D25: =COUNTIFS('2. 위험 식별 및 평가'!$D$10:$D$41,C25,'2. 위험 식별 및 평가'!$K$10:$K$41,"Yes") -> 2 | E25: =SUMIFS('2. 위험 식별 및 평가'!$H$10:$H$41,'2. 위험 식별 및 평가'!$D$10:$D$41,'평가 결과(요약)'!C25,'2. 위험 식별 및 평가'!$K$10:$K$41,"yes") -> 6 | F25: =COUNTIFS('2. 위험 식별 및 평가'!$D$10:$D$41,C25,'2. 위험 식별 및 평가'!$N$10:$N$41,"Yes") -> 0 | G25: =SUMIFS('2. 위험 식별 및 평가'!$H$10:$H$41,'2. 위험 식별 및 평가'!$D$10:$D$41,'평가 결과(요약)'!C25,'2. 위험 식별 및 평가'!$N$10:$N$41,"yes") -> 0 | H25: =COUNTIFS('2. 위험 식별 및 평가'!$D$10:$D$41,C25,'2. 위험 식별 및 평가'!$T$10:$T$41,">0") -> 0 | I25: =SUMIF('3. 잔여 AI 위험 평가'!$D$7:$D$38,'평가 결과(요약)'!C25,'3. 잔여 AI 위험 평가'!$T$7:$T$38) -> 0
B26: 보안성 원칙 | C26: 프라이버시 | D26: =COUNTIFS('2. 위험 식별 및 평가'!$D$10:$D$41,C26,'2. 위험 식별 및 평가'!$K$10:$K$41,"Yes") -> 1 | E26: =SUMIFS('2. 위험 식별 및 평가'!$H$10:$H$41,'2. 위험 식별 및 평가'!$D$10:$D$41,'평가 결과(요약)'!C26,'2. 위험 식별 및 평가'!$K$10:$K$41,"yes") -> 2 | F26: =COUNTIFS('2. 위험 식별 및 평가'!$D$10:$D$41,C26,'2. 위험 식별 및 평가'!$N$10:$N$41,"Yes") -> 0 | G26: =SUMIFS('2. 위험 식별 및 평가'!$H$10:$H$41,'2. 위험 식별 및 평가'!$D$10:$D$41,'평가 결과(요약)'!C26,'2. 위험 식별 및 평가'!$N$10:$N$41,"yes") -> 0 | H26: =COUNTIFS('2. 위험 식별 및 평가'!$D$10:$D$41,C26,'2. 위험 식별 및 평가'!$T$10:$T$41,">0") -> 0 | I26: =SUMIF('3. 잔여 AI 위험 평가'!$D$7:$D$38,'평가 결과(요약)'!C26,'3. 잔여 AI 위험 평가'!$T$7:$T$38) -> 0
B27: =B26&" 합계" -> 보안성 원칙 합계 | D27: =SUBTOTAL(9,D23:D26) -> 7 | E27: =SUBTOTAL(9,E23:E26) -> 16 | F27: =SUBTOTAL(9,F23:F26) -> 0 | G27: =SUBTOTAL(9,G23:G26) -> 0 | H27: =SUBTOTAL(9,H23:H26) -> 0 | I27: =SUBTOTAL(9,I23:I26) -> 0
B28: 총계 | D28: =SUBTOTAL(9,D8:D27) -> 23 | E28: =SUBTOTAL(9,E8:E27) -> 68 | F28: =SUBTOTAL(9,F8:F27) -> 3 | G28: =SUBTOTAL(9,G8:G27) -> 10 | H28: =SUBTOTAL(9,H8:H27) -> 2 | I28: =SUBTOTAL(9,I8:I27) -> 2

Sheet AI 위험평가 기준자료
B2: 기준자료 - 세부 위험, 완화방안 답변, 위험 등급 구간
B4: AI RMF 기반 세부 위험 정의 | G4: 2. 세부 위험별 정의
B5: Lv 1 | C5: 문항 수 | D5: 영역 총점 | G5: Lv1 | H5: Lv2 | I5: Lv3 | J5: 배점 | K5: 검토 담당
B6: 합법성 원칙 | C6: =COUNTIF($G$6:$G$37,B6) -> 6 | D6: =SUMIF($G$6:$G$37,B6,$J$6:$J$37) -> 20 | F6: 1 | G6: 합법성 원칙 | H6: 금융소비자보호법 위반 가능성 | I6: 고지 의무 위반 | J6: 4 | K6: AI 서비스기획
B7: 신뢰성 원칙 | C7: =COUNTIF($G$6:$G$37,B7) -> 11 | D7: =SUMIF($G$6:$G$37,B7,$J$6:$J$37) -> 30 | F7: 2 | G7: 합법성 원칙 | H7: 금융소비자보호법 위반 가능성 | I7: 설명 의무/부당권유행위 위반 | J7: 4 | K7: AI 서비스기획
B8: 신의성실의 원칙 | C8: =COUNTIF($G$6:$G$37,B8) -> 4 | D8: =SUMIF($G$6:$G$37,B8,$J$6:$J$37) -> 20 | F8: 3 | G8: 합법성 원칙 | H8: AI기본법 위반 가능성 | I8: AI 기본법 위반 | J8: 4 | K8: AI 서비스기획
B9: 보안성 원칙 | C9: =COUNTIF($G$6:$G$37,B9) -> 11 | D9: =SUMIF($G$6:$G$37,B9,$J$6:$J$37) -> 30 | F9: 4 | G9: 합법성 원칙 | H9: 데이터 관련법 위반 가능성 | I9: 민감 정보 추출/재식별 | J9: 2 | K9: AI 서비스기획
C10: =SUM(C6:C9) -> 32 | D10: =SUM(D6:D9) -> 100 | F10: 5 | G10: 합법성 원칙 | H10: 데이터 관련법 위반 가능성 | I10: 개인정보의 부적절한 처리 | J10: 2 | K10: AI 서비스기획
F11: 6 | G11: 합법성 원칙 | H11: 개별 업권법 위반 가능성 | I11: 금융관련 법 위반 | J11: 4 | K11: AI 서비스기획
B12: 3. 위험 등급 구간 | F12: 7 | G12: 신뢰성 원칙 | H12: 품질 | I12: 데이터 불충분성 | J12: 2 | K12: AI 개발
B13: 위험 수준 | C13: 하단 | D13: 상단 | F13: 8 | G13: 신뢰성 원칙 | H13: 품질 | I13: 데이터 정확성 부족 | J13: 2 | K13: AI 개발
B14: 허용불가 서비스 | C14: 75 | D14: 100 | F14: 9 | G14: 신뢰성 원칙 | H14: 품질 | I14: 학습 데이터 오염/손실 | J14: 2 | K14: AI 개발
B15: 고위험 서비스 | C15: 50 | D15: 74 | F15: 10 | G15: 신뢰성 원칙 | H15: 편향성 | I15: 데이터 편향성 | J15: 6 | K15: AI 개발
B16: 중위험 서비스 | C16: 25 | D16: 49 | F16: 11 | G16: 신뢰성 원칙 | H16: 공정성 | I16: 공정성 위반 | J16: 6 | K16: AI 개발
B17: 저위험 서비스 | C17: 0 | D17: 24 | F17: 12 | G17: 신뢰성 원칙 | H17: 설명가능성 | I17: 설명 가능성/투명성 부족 | J17: 6 | K17: AI 서비스기획
F18: 13 | G18: 신뢰성 원칙 | H18: 성능 | I18: 모델 과대/과소 적합 위험 | J18: 1 | K18: AI 개발
F19: 14 | G19: 신뢰성 원칙 | H19: 성능 | I19: 모델 드리프트 위험 | J19: 1 | K19: AI 개발
B20: 4. 완화방안/잔여 위험 수행 여부 | F20: 15 | G20: 신뢰성 원칙 | H20: 성능 | I20: 모델 붕괴 (Model Collapse) | J20: 1 | K20: AI 개발
B21: 내용 | C21: 구분 | D21: 완화수준 | F21: 16 | G21: 신뢰성 원칙 | H21: 성능 | I21: 모델 성능 지표 부적합 | J21: 1 | K21: AI 서비스기획
B22: 완전히 완화 | C22: O | D22: 0.0 | F22: 17 | G22: 신뢰성 원칙 | H22: 성능 | I22: 부정확한 정보 출력 (환각) | J22: 2 | K22: AI 서비스기획
B23: 완화방안 적용 후에도 잔여위험 존재 | C23: △ | D23: 0.5 | F23: 18 | G23: 신의성실의 원칙 | H23: 계약 권리 침해 | I23: 의사결정 기능 오작동 | J23: 6 | K23: AI 서비스기획
B24: 완화방안 적용 후에도 위험 수준 동일 | C24: X | D24: 1.0 | F24: 19 | G24: 신의성실의 원칙 | H24: 책임 투명성 | I24: 책임소재 불명확 | J24: 6 | K24: AI 서비스기획
F25: 20 | G25: 신의성실의 원칙 | H25: 소비자 보호방안 | I25: 소비자 보호방안 미확보 | J25: 4 | K25: AI 서비스기획
F26: 21 | G26: 신의성실의 원칙 | H26: 소비자 보호방안 | I26: 소비자의 편의성 저하 | J26: 4 | K26: AI 서비스기획
F27: 22 | G27: 보안성 원칙 | H27: 보안 | I27: 데이터 유출 | J27: 2 | K27: AI 개발
F28: 23 | G28: 보안성 원칙 | H28: 보안 | I28: 무단 모델 추출 (Model Extraction) | J28: 2 | K28: AI 개발
F29: 24 | G29: 보안성 원칙 | H29: 보안 | I29: 사이버 범죄 지원 | J29: 2 | K29: AI 서비스기획
F30: 25 | G30: 보안성 원칙 | H30: 보안 | I30: 적대적 공격 취약성 (Evasion Attack) | J30: 2 | K30: AI 개발
F31: 26 | G31: 보안성 원칙 | H31: 보안 | I31: 가짜 컨텐츠 사기 피해 | J31: 2 | K31: AI 서비스기획
F32: 27 | G32: 보안성 원칙 | H32: 안정성 | I32: 시스템 안정성 | J32: 8 | K32: AI 개발
F33: 28 | G33: 보안성 원칙 | H33: 위탁/관리 | I33: AI 서비스 외부 위탁 | J33: 3 | K33: AI 서비스기획
F34: 29 | G34: 보안성 원칙 | H34: 위탁/관리 | I34: 모델 외부위탁 위험 | J34: 3 | K34: AI 서비스기획
F35: 30 | G35: 보안성 원칙 | H35: 프라이버시 | I35: 개인 식별 정보(PII) 노출 | J35: 2 | K35: AI 서비스기획
F36: 31 | G36: 보안성 원칙 | H36: 프라이버시 | I36: 모델 인버전 공격 (Model Inversion Attack) | J36: 2 | K36: AI 개발
F37: 32 | G37: 보안성 원칙 | H37: 프라이버시 | I37: 필요 이상 데이터 수집 | J37: 2 | K37: AI 서비스기획

Sheet Reference)

Sheet AI 위험 정의 상세
B2: AI 세부 위험
B4: AI RMF 기반 세부 위험 정의 | E4: As-Was | O4: 사용자범위 | P4: 사용자범위 | Q4: 산출물특성 | R4: 산출물특성 | S4: 산출물특성 | T4: 의사결정영향도 | U4: 의사결정영향도 | V4: 의사결정영향도 | W4: 데이터민감도 | X4: 데이터민감도 | Y4: 데이터민감도
B5: 대분류 (Level 1) | C5: 중분류 (Level 2) | D5: 소분류 (Level 3) | E5: 대분류 (Level 1) _As-Was | F5: 중분류 (Level 2) _As-Was | G5: 소분류 (Level 3) _As-Was | H5: 정의_As-Was | I5: 정의 | J5: 평가 방안 | K5: 완화 방안 | L5: 배점 | M5: ref | N5: 담당 | O5: 대고객 서비스 | P5: 임직원 서비스 | Q5: 생성형 | R5: 판단형 | S5: 복합형 (생성형+판단형) | T5: 인간결정형 (HITL) | U5: 인간감독형 (HOTL) | V5: 자율운영형 (HOVL, HOUTL) | W5: 비개인정보 | X5: 개인정보 | Y5: 민감·신용정보
A6: 1 | B6: 합법성 원칙 | C6: 금융소비자보호법 위반 가능성 | D6: 고지 의무 위반 | E6: AI 서비스 위험 (AI Service Risk) | F6: 거버넌스 및 제도적 위험 | G6: 고지 의무 위반 | H6: 대고객 AI 서비스 운영 시 고지의무 대상 서비스에 대해서는 고지 절차 수행해야 하나 하지 않아서 제재를 받게 될 위험 | I6: 대고객 AI 서비스 운영 시 고지의무 대상 서비스에 대해서는 적합한 내용으로 고지 절차를 수행해야 하나 하지 않아서 제재를 받게 될 위험 (AI RMF 기준: 적합성/적정성 원칙, 불공정 영업행위 금지 원칙/상품 광고 규제) | J6: § sLLM 기반 문구 적정성 검사(Content Validity): 법령에서 요구하는 필수 핵심 내용이 고지 문구에 포함되었는지 검사 § 자동화 로직: sLLM를 활용하여 고지 문구 내에 [AI 활용, 결과 도출 근거, 이의제기 권리, 담당부서 연락처] 등의 필수 키워드가 포함되어 있는지 확인 하나라도 누락 시 '주의' 등급을 부여 § 체크 리스트를 통한 사용자 판단 - 고지 절차 존재 및 고지 내용의 적정 여부 등 확인 | K6: § 고지 절차 자동화 및 표준화: ITSM의 기획 단계에서 고지 의무 대상을 자동으로 식별하고, 표준화된 고지 템플릿을 서비스 설계에 반영하도록 강제화 § 관리시스템: 서비스 기획 및 AI 서비스 개발계획 수립 시 고지 항목을 정의하고 서비스 승인 절차에서 이행 여부를 최종 확정 § 평가시스템: 실제 운영 환경에서 고지 로그가 정상 적재되는지 모니터링하고, 검수+피드백 시스템을 통해 고지 문구의 개선 사항을 지속적으로 반영 | L6: 4 | N6: AI 서비스기획 | O6: Yes | Q6: Yes | R6: Yes | S6: Yes | T6: Yes | U6: Yes | V6: Yes | W6: Yes | X6: Yes | Y6: Yes
A7: =A6+1 -> 2 | B7: 합법성 원칙 | C7: 금융소비자보호법 위반 가능성 | D7: 설명 의무/부당권유행위 위반 | E7: AI 서비스 위험 (AI Service Risk) | F7: 거버넌스 및 제도적 위험 | G7: 설명 의무 위반 | H7: 대고객 AI 서비스 운영 시 설명 의무 대상 서비스에 대해서는 설명 절차 수행해야 하나 사전에 인지하지 못할 위험 | I7: 대고객 AI 서비스 운영 시 설명 의무 대상 서비스에 대해서는 설명 절차 수행해야 하나, 사전에 인지하지 못하거나 잘못된 정보를 제공할 위험 (AI RMF 기준: 설명의무/부당권유행위 금지 원칙) | J7: § 설명 정합성 지수 (EA-Score): 로직: AI가 제시한 설명(Explanation)이 실제 모델의 피처 기여도(Feature Importance)와 얼마나 일치하는지 측정 기준: 정합성 98% 이상 '우수', 90% 미만 ‘주의'. § XAI 신뢰도 검증 (XF-Score): SHAP, LIME 등의 기술을 사용하여 모델의 판단 근거를 시각화하고, 이를 비즈니스 규칙과 대조하여 논리적 타당성을 검토 § 부당권유 탐지 모니터링: 특정 상품의 추천 빈도가 통계적으로 비정상적으로 높거나, 수익성 위주의 편향이 발견되는지 집단 간 격차 지수(DI)를 변형하여 측정 | K7: § 관리시스템: AI 위험/영향 식별 단계에서 설명 의무 대상 여부를 판정하고, 위반 시 위험성 재평가 프로세스를 수행 § 평가시스템: RAG 기반 데이터 Faithful 점수평가를 통해 생성된 설명이 실제 규정집이나 데이터에 기반하고 있는지 실시간 검증 § 설명 가능한 AI(xAI) 워크플로우 의무화: 결정 결과와 함께 핵심 변수 3~5개를 소비자 화면에 자동으로 노출하는 기능을 설계 단계(ITSM)에서 필수화 | L7: 4 | M7: 韓 국가기술표준원_인공지능 윤리에 대한 이해관계자 공동 영향 요소 및 유스케이스 수집 템플릿 | N7: AI 서비스기획 | O7: Yes | Q7: Yes | R7: Yes | S7: Yes | T7: Yes | U7: Yes | V7: Yes | W7: Yes | X7: Yes | Y7: Yes
A8: =A7+1 -> 3 | B8: 합법성 원칙 | C8: AI기본법 위반 가능성 | D8: AI 기본법 위반 | I8: AI 기본법의 주요 의무를 위반하거나 법령의 요구사항을 누락하여 서비스를 기획 및 운영할 위험 | J8: § 법규 준수 진단 (Compliance Score) 로직: AI 기본법의 요구사항 기반 체크리스트 (예: 투명성 확보 의무에 따른 고지 의무 등)를 시스템화하여 이행 여부를 점수화 지표: 100점 만점 기준 100점 필수 (법적 의무 사항은 예외 없이 준수해야 함) § AI 영향 평가 (AIA, AI Impact Assessment): 관리시스템 내 'AI 위험/영향/안전성 식별/평가' 단계를 통해 해당 서비스가 인권, 안전, 사회적 가치에 미치는 영향을 사전에 분석 § 증적 완결성 검증: 법적 분쟁 시 제출할 수 있는 학습 데이터 출처, 알고리즘 설명서, 안전성 테스트 결과가 평가 이력 관리에 누락 없이 저장되어 있는지 자동 스캔 | K8: § Legal-Tech 기반 가드레일: sLLM 기반 법령 스캐너를 활용하여 서비스 기획서 및 약관이 최신 AI 기본법 및 시행령에 부합하는지 실시간 검토 § 단계별 게이트키핑 (Gate-keeping): ITSM 워크플로우 상에서 법무/컴플라이언스 부서의 승인 없이는 모델 배포(Deployment)가 불가능하도록 시스템 통제장치를 설정 § 신뢰성 검인증 연계 : 제3자 인증 기관이나 국가 공인 신뢰성 검인증 지표를 평가시스템에 등록하고, 이를 통과한 모델만 운영할 수 있도록 관리 § 책임 소재의 명확화: 관리시스템 내에 각 AI 서비스별 'AI 관리책임자'를 명시하고, 생애주기별 R&R을 디지털 증적으로 남겨 책임성을 강화 | L8: 4 | N8: AI 서비스기획 | O8: Yes | P8: Yes | Q8: Yes | R8: Yes | S8: Yes | T8: Yes | U8: Yes | V8: Yes | W8: Yes | X8: Yes | Y8: Yes
A9: =A8+1 -> 4 | B9: 합법성 원칙 | C9: 데이터 관련법 위반 가능성 | D9: 민감 정보 추출/재식별 | E9: 데이터 위험 (Data Risk) | F9: 데이터 프라이버시 위험 | G9: 민감 정보 추출/재식별 | H9: AI의 추론 능력을 악용하여 개인의 민감 정보(건강, 위치 등)를 추출, 재식별, 연결, 추론함으로써 프라이버시 침해가 심화되고 개인 데이터가 악용 및 노출될 위험 | I9: AI의 추론 능력을 악용하여 개인의 민감 정보(건강, 위치 등)를 추출, 재식별, 연결, 추론함으로써 프라이버시 침해가 심화되고 개인 데이터가 악용 및 노출될 위험 | J9: § 민감정보 생성 유발 레드티밍: 공격 프롬프트 생성을 자동화는 레드티밍 솔루션을 활용하여 민감정보 유출을 시도 - '공격 타입: <민감정보 유출> 설정 / 프롬프트: <공격 시나리오> 입력’으로 공격 시나리오 자동 생성 - 공격 성공 판단: 공격 시나리오 입/출력에 민감정보 포함 여부 - 위험 점수: (공격 성공 / 전체 공격 시도) X 100 | K9: § 일반화 및 대체: 민감 데이터를 일반화하고 범주화하여 식별력을 낮춤 § 출력값 라운딩(Rounding) 및 제한: 모델 예측 확률을 정밀하게 주지 않고, 대략적인 범위로 제공 | L9: 2 | M9: 개인정보법 제23조 등 위치정보법 제3장 美 대통령 행정명령 14110 (2023.10) | N9: AI 서비스기획 | O9: Yes | Q9: Yes | S9: Yes | U9: Yes | V9: Yes | X9: Yes | Y9: Yes
A10: =A9+1 -> 5 | B10: 합법성 원칙 | C10: 데이터 관련법 위반 가능성 | D10: 개인정보의 부적절한 처리 | I10: 정보주체로부터 동의받지 않은 목적으로 모델 훈련에 사용 등 개인정보를 처리하거나 기타 데이터 사용, 이동, 판매에 관련한 법령을 위반할 위험 (개인정보보호법, 신용정보법, 위치정보법 등) | J10: § 데이터 법령 준수 진단 (Compliance Score) - 로직: 개인정보법 및 신용정보법 상 요건 기반 체크리스트 (예: AI 학습 및 모델 개선 목적 개인정보 수집 이용 동의 징구 및 해당 데이터 한정 모델 학습 여부 등)를 시스템화하여 이행 여부를 점수화 - 지표: 100점 만점 기준 100점 필수 (법적 의무 사항은 예외 없이 준수해야 함) § 접근 로그 감사: 데이터 파이프라인 로그에 민감정보가 저장된 DB 테이블에 접근한 이력이 있는지 분석 - 공격 성공 판단: 데이터 파이프라인 로그에 민감정보에 접근한 이력이 있는 경우 - 위험 점수: 민감정보에 접근했는지 여부 | K10: § AI 학습용 데이터 구분 동의: 수집 시점에 AI 학습용 데이터는 명확히 구분하여 동의를 획득하도록 UI 설계 § 민감정보 분리 보관: 민감정보는 물리적/논리적으로 완전히 분리된 별도 DB에 암호화하여 저장 | L10: 2 | M10: 개인정보보호법 제15조, 제18조, 제20조 등 신용정보법 제15조 등 위치정보법 제3장 | N10: AI 서비스기획 | O10: Yes | Q10: Yes | R10: Yes | S10: Yes | U10: Yes | V10: Yes | X10: Yes | Y10: Yes
A11: =A10+1 -> 6 | B11: 합법성 원칙 | C11: 개별 업권법 위반 가능성 | D11: 금융관련 법 위반 | I11: AI 상품·서비스를 출시 및 운용하는 과정에서 자본시장법 등 개별 금융업권 법규를 위반할 수 있는 위험 | J11: § 이상금융거래 탐지 시스템(FDS) 연동: AI 이용 방식이 법규 위반 패턴과 유사한지 판단 가능 - 공격 성공 판단: AI 상품 및 서비스 관련 요청 결과가 FDS에서 이상거래로 탐지 - 위험 점수 = (탐지 성공 / 전체 상품 및 서비스 관련 요청) X 100 § 법규 준수 진단 (Compliance Score) - 로직: 금융투자 관련 법령 상 요건 기반 체크리스트 (예: 자본시장법 제99조(투자일임보고서의 교부) 요구사항 등)를 시스템화하여 이행 여부를 점수화 - 지표: 100점 만점 기준 100점 필수 (법적 의무 사항은 예외 없이 준수해야 함) | K11: § Human-In-the-Loop(HITL) 개념 적용: 잘못된 판단으로 고객에게 큰 손해가 발생하거나 위법 가능성 높은 상품이나 서비스는 마지막 단계에서 해당 근거를 설명하고 인간이 판단할 수 있도록 하는 프로세스 적용 § 진단 결과 발견 사항에 대한 개선 수행: 체크리스트를 통한 점검 결과 사전 발견한 미흡 사항을 확인하고 각 사항에 따른 완화 방안을 수립 및 이행하여, 금융 관련 법령을 준수하여 AI 서비스 및 시스템을 개발 및 운영 | L11: 4 | N11: AI 서비스기획 | O11: Yes | P11: Yes | Q11: Yes | S11: Yes | V11: Yes | W11: Yes | X11: Yes | Y11: Yes
A12: =A11+1 -> 7 | B12: 신뢰성 원칙 | C12: 품질 | D12: 데이터 불충분성 | E12: 데이터 위험 (Data Risk) | F12: 데이터 품질 및 오염 위험 | G12: 데이터 불충분성 | H12: 데이터셋이 AI 시스템의 상황 또는 의도된 사용을 정확하게 대표하지 못하거나, 실제 상황을 반영하지 못하여 AI 시스템의 신뢰성에 영향을 미칠 수 있는 위험 | I12: 데이터셋이 AI 시스템의 상황 또는 의도된 사용을 정확하게 대표하지 못하거나, 실제 상황을 반영하지 못하여 AI 시스템의 신뢰성에 영향을 미칠 수 있는 위험 | J12: § 평가 지표: 신뢰구간(Confidence Interval, CI). § 판단 기준: 신뢰구간(CI) > 0.2인 경우, 예측 결과의 불확실성이 높은 것으로 간주하여 시스템 경고를 발생시키고 재학습 우선순위를 상향 조정 | K12: § 능동적 학습(Active Learning) 기반 보강: 모델이 불확실하다고 판단하는 영역(CI > 0.2)의 데이터를 우선적으로 식별하여 집중적으로 수집하고 라벨링 § 데이터 증강(Data Augmentation): 합성 데이터 생성이나 통계적 오버샘플링을 통해 데이터가 희소한 구간을 보강하여 모델의 노출 빈도를 높힘 § 모델 기반 완화: 유사 도메인의 대규모 데이터를 활용한 전이 학습(Transfer Learning)을 적용하거나, 앙상블 기법을 통해 개별 모델의 불확실성을 상쇄 § 추론 제어 및 가드레일: 불확실성이 높은 예측 결과에 대해서는 AI의 독자적인 결정을 제한하고, 전문가(Human-in-the-Loop)의 개입을 요청하거나 사용자에게 불확실성을 사전에 고지 | L12: 2 | M12: 美 NIST AI RMF 1.0 (2023.1) | N12: AI 개발 | O12: Yes | P12: Yes | Q12: Yes | R12: Yes | S12: Yes | U12: Yes | V12: Yes | X12: Yes | Y12: Yes
